Workbook

Sheet INSTRUCTIONS
A3: ⚠️ STOP! DO NOT ENTER DATA UNTIL YOU HAVE SAVED A COPY ⚠️
A5: Instruction: "This is a Read-Only Template. To start a new competition, go to FILE > CREATE A COPY > SAVE A COPY ONLINE and name it after today's match."
A7: To start a new match, select File >Open>View all files> Open the copy you names as above . This keeps the template clean for next time.
A9: General Rule for Data Entry
A10: Don't Change any boxes with Red Background
A11: 1. PRE-MATCH (Registration Tab)
A13: Complete Early Before competition Starts: Complete Name and Angler and opt in to Secret Pairs (Yes or No) columns only. You can ignore the other columns at the right side of the sheet at this time.
A14: Team Grouping: List team members in blocks of four (e.g., Rows 1-4 = Team A).
A15: The Spelling Rule: Names must match catch cards exactly. "Chris" is not "Christopher" to a computer!
A16: Late Entries: Add new anglers to the next empty row and assign their Team Name immediately.
A19: 2. DURING MATCH (Day 1 & Day 2 Tab)
A21: Data Entry: You only need to enter data in zone, length, species, fish count and biggest fish. Do not change name or points they are placed there automatically.
... A31: Automated Results: These sheets are locked. If a number looks wrong, go back to the Day 1/Day 2 tabs and check your entry.
A36: 4
A37: 4. Locked Tabs ( Day 1 Zone, Day 2 Zone, Team Standings, Biggest Fish, Secret Pairs, Charts)
A39: These tabs show data only. You can safely view them.
A40: The tabs automatically update during the course of the competition.
A42: 5) Secret Pairs ( Optional)
A43: These instuctions should only be completed once all the data has been entered,and competition is closed. Go to Registration page and follow instructions on the page. You can click the randomiser button more than once but once you are happy that its random you need to lock the results so winners are locked in. Follow the instructions to lock selection. To see the winners go to the secret Pairs Tab.
A45: 📤 5. SHARING & PUBLISHING
A47: To Publish Full tables from Excell
A49: Use File menu in Excell > Export > Save as PDF. You can then dpownload and share the pdf as normal via Whatsapp or other alternative.

Sheet DATA_IMPORT

Sheet REGISTRATION
A1: ID | B1: ANGLER NAME | C1: TEAM | D1: OPT IN | N1: SEED | O1: ORDER
A2: 1 | B2: =IF(DATA_IMPORT!A2="", "", DATA_IMPORT!A2) | C2: =IF(DATA_IMPORT!B2="", "", DATA_IMPORT!B2) | D2: No | N2: =$Q$4 + RAND() -> 0.76470624 | O2: =IF(N2="", "", _xlfn.RANK.EQ(N2, $N$2:$N$120) + COUNTIF($N$2:N2, N2) - 1) -> 29 | Q2: Click Red Box Below to Randomise Random Pairs. You can click as many times as you want. Once tick is missing from the box winners are ready.
A3: 2 | B3: =IF(DATA_IMPORT!A3="", "", DATA_IMPORT!A3) | C3: =IF(DATA_IMPORT!B3="", "", DATA_IMPORT!B3) | D3: Yes | N3: =$Q$4 + RAND() -> 0.097843044 | O3: =IF(N3="", "", _xlfn.RANK.EQ(N3, $N$2:$N$120) + COUNTIF($N$2:N3, N3) - 1) -> 114
A4: 3 | B4: =IF(DATA_IMPORT!A4="", "", DATA_IMPORT!A4) | C4: =IF(DATA_IMPORT!B4="", "", DATA_IMPORT!B4) | D4: Yes | N4: =$Q$4 + RAND() -> 0.34180473 | O4: =IF(N4="", "", _xlfn.RANK.EQ(N4, $N$2:$N$120) + COUNTIF($N$2:N4, N4) - 1) -> 88 | Q4: FALSE
A5: 4 | B5: =IF(DATA_IMPORT!A5="", "", DATA_IMPORT!A5) | C5: =IF(DATA_IMPORT!B5="", "", DATA_IMPORT!B5) | D5: Yes | N5: =$Q$4 + RAND() -> 0.51468505 | O5: =IF(N5="", "", _xlfn.RANK.EQ(N5, $N$2:$N$120) + COUNTIF($N$2:N5, N5) - 1) -> 64
A6: 5 | B6: =IF(DATA_IMPORT!A6="", "", DATA_IMPORT!A6) | C6: =IF(DATA_IMPORT!B6="", "", DATA_IMPORT!B6) | D6: Yes | N6: =$Q$4 + RAND() -> 0.55751523 | O6: =IF(N6="", "", _xlfn.RANK.EQ(N6, $N$2:$N$120) + COUNTIF($N$2:N6, N6) - 1) -> 60 | Q6: TO REVEAL WINNERS: Go to the SECRET PAIRS FINAL tab.
A7: 6 | B7: =IF(DATA_IMPORT!A7="", "", DATA_IMPORT!A7) | C7: =IF(DATA_IMPORT!B7="", "", DATA_IMPORT!B7) | D7: Yes | N7: =$Q$4 + RAND() -> 0.96534284 | O7: =IF(N7="", "", _xlfn.RANK.EQ(N7, $N$2:$N$120) + COUNTIF($N$2:N7, N7) - 1) -> 4
A8: 7 | B8: =IF(DATA_IMPORT!A8="", "", DATA_IMPORT!A8) | C8: =IF(DATA_IMPORT!B8="", "", DATA_IMPORT!B8) | D8: Yes | N8: =$Q$4 + RAND() -> 0.7790422 | O8: =IF(N8="", "", _xlfn.RANK.EQ(N8, $N$2:$N$120) + COUNTIF($N$2:N8, N8) - 1) -> 27
A9: 8 | B9: =IF(DATA_IMPORT!A9="", "", DATA_IMPORT!A9) | C9: =IF(DATA_IMPORT!B9="", "", DATA_IMPORT!B9) | D9: Yes | N9: =$Q$4 + RAND() -> 0.013633362 | O9: =IF(N9="", "", _xlfn.RANK.EQ(N9, $N$2:$N$120) + COUNTIF($N$2:N9, N9) - 1) -> 119
A10: 9 | B10: =IF(DATA_IMPORT!A10="", "", DATA_IMPORT!A10) | C10: =IF(DATA_IMPORT!B10="", "", DATA_IMPORT!B10) | D10: Yes | N10: =$Q$4 + RAND() -> 0.57271529 | O10: =IF(N10="", "", _xlfn.RANK.EQ(N10, $N$2:$N$120) + COUNTIF($N$2:N10, N10) - 1) -> 56
A11: 10 | B11: =IF(DATA_IMPORT!A11="", "", DATA_IMPORT!A11) | C11: =IF(DATA_IMPORT!B11="", "", DATA_IMPORT!B11) | D11: Yes | N11: =$Q$4 + RAND() -> 0.37379334 | O11: =IF(N11="", "", _xlfn.RANK.EQ(N11, $N$2:$N$120) + COUNTIF($N$2:N11, N11) - 1) -> 84
A12: 11 | B12: =IF(DATA_IMPORT!A12="", "", DATA_IMPORT!A12) | C12: =IF(DATA_IMPORT!B12="", "", DATA_IMPORT!B12) | D12: Yes | N12: =$Q$4 + RAND() -> 0.56640989 | O12: =IF(N12="", "", _xlfn.RANK.EQ(N12, $N$2:$N$120) + COUNTIF($N$2:N12, N12) - 1) -> 58
A13: 12 | B13: =IF(DATA_IMPORT!A13="", "", DATA_IMPORT!A13) | C13: =IF(DATA_IMPORT!B13="", "", DATA_IMPORT!B13) | D13: Yes | N13: =$Q$4 + RAND() -> 0.29333424 | O13: =IF(N13="", "", _xlfn.RANK.EQ(N13, $N$2:$N$120) + COUNTIF($N$2:N13, N13) - 1) -> 96
A14: 13 | B14: =IF(DATA_IMPORT!A14="", "", DATA_IMPORT!A14) | C14: =IF(DATA_IMPORT!B14="", "", DATA_IMPORT!B14) | D14: Yes | N14: =$Q$4 + RAND() -> 0.4514847 | O14: =IF(N14="", "", _xlfn.RANK.EQ(N14, $N$2:$N$120) + COUNTIF($N$2:N14, N14) - 1) -> 73
A15: 14 | B15: =IF(DATA_IMPORT!A15="", "", DATA_IMPORT!A15) | C15: =IF(DATA_IMPORT!B15="", "", DATA_IMPORT!B15) | D15: Yes | N15: =$Q$4 + RAND() -> 0.72270001 | O15: =IF(N15="", "", _xlfn.RANK.EQ(N15, $N$2:$N$120) + COUNTIF($N$2:N15, N15) - 1) -> 36
A16: 15 | B16: =IF(DATA_IMPORT!A16="", "", DATA_IMPORT!A16) | C16: =IF(DATA_IMPORT!B16="", "", DATA_IMPORT!B16) | D16: Yes | N16: =$Q$4 + RAND() -> 0.84242064 | O16: =IF(N16="", "", _xlfn.RANK.EQ(N16, $N$2:$N$120) + COUNTIF($N$2:N16, N16) - 1) -> 16
A17: 16 | B17: =IF(DATA_IMPORT!A17="", "", DATA_IMPORT!A17) | C17: =IF(DATA_IMPORT!B17="", "", DATA_IMPORT!B17) | D17: Yes | N17: =$Q$4 + RAND() -> 0.2010477 | O17: =IF(N17="", "", _xlfn.RANK.EQ(N17, $N$2:$N$120) + COUNTIF($N$2:N17, N17) - 1) -> 103
A18: 17 | B18: =IF(DATA_IMPORT!A18="", "", DATA_IMPORT!A18) | C18: =IF(DATA_IMPORT!B18="", "", DATA_IMPORT!B18) | D18: Yes | N18: =$Q$4 + RAND() -> 0.64611833 | O18: =IF(N18="", "", _xlfn.RANK.EQ(N18, $N$2:$N$120) + COUNTIF($N$2:N18, N18) - 1) -> 46 | Q18: For Admin Only: To Unlock Randomiser
A19: 18 | B19: =IF(DATA_IMPORT!A19="", "", DATA_IMPORT!A19) | C19: =IF(DATA_IMPORT!B19="", "", DATA_IMPORT!B19) | D19: Yes | N19: =$Q$4 + RAND() -> 0.64735311 | O19: =IF(N19="", "", _xlfn.RANK.EQ(N19, $N$2:$N$120) + COUNTIF($N$2:N19, N19) - 1) -> 44 | Q19: Paste this formula into cell N2 =$Q$4 + RAND()
A20: 19 | B20: =IF(DATA_IMPORT!A20="", "", DATA_IMPORT!A20) | C20: =IF(DATA_IMPORT!B20="", "", DATA_IMPORT!B20) | D20: Yes | N20: =$Q$4 + RAND() -> 0.9678527 | O20: =IF(N20="", "", _xlfn.RANK.EQ(N20, $N$2:$N$120) + COUNTIF($N$2:N20, N20) - 1) -> 3 | Q20: Click the cell where you just pasted the formula (e.g., N2).
A21: 20 | B21: =IF(DATA_IMPORT!A21="", "", DATA_IMPORT!A21) | C21: =IF(DATA_IMPORT!B21="", "", DATA_IMPORT!B21) | D21: Yes | N21: =$Q$4 + RAND() -> 0.22828534 | O21: =IF(N21="", "", _xlfn.RANK.EQ(N21, $N$2:$N$120) + COUNTIF($N$2:N21, N21) - 1) -> 99 | Q21: Grab the tiny green square (the fill handle) in the bottom-right corner.
A22: 21 | B22: =IF(DATA_IMPORT!A22="", "", DATA_IMPORT!A22) | C22: =IF(DATA_IMPORT!B22="", "", DATA_IMPORT!B22) | D22: Yes | N22: =$Q$4 + RAND() -> 0.58652724 | O22: =IF(N22="", "", _xlfn.RANK.EQ(N22, $N$2:$N$120) + COUNTIF($N$2:N22, N22) - 1) -> 54 | Q22: Drag it down to the bottom of your angler list.
A23: 22 | B23: =IF(DATA_IMPORT!A23="", "", DATA_IMPORT!A23) | C23: =IF(DATA_IMPORT!B23="", "", DATA_IMPORT!B23) | D23: Yes | N23: =$Q$4 + RAND() -> 0.51267464 | O23: =IF(N23="", "", _xlfn.RANK.EQ(N23, $N$2:$N$120) + COUNTIF($N$2:N23, N23) - 1) -> 65 | Q23: Randomiser is working again
A24: 23 | B24: =IF(DATA_IMPORT!A24="", "", DATA_IMPORT!A24) | C24: =IF(DATA_IMPORT!B24="", "", DATA_IMPORT!B24) | D24: Yes | N24: =$Q$4 + RAND() -> 0.57638452 | O24: =IF(N24="", "", _xlfn.RANK.EQ(N24, $N$2:$N$120) + COUNTIF($N$2:N24, N24) - 1) -> 55
A25: 24 | B25: =IF(DATA_IMPORT!A25="", "", DATA_IMPORT!A25) | C25: =IF(DATA_IMPORT!B25="", "", DATA_IMPORT!B25) | D25: Yes | N25: =$Q$4 + RAND() -> 0.72674559 | O25: =IF(N25="", "", _xlfn.RANK.EQ(N25, $N$2:$N$120) + COUNTIF($N$2:N25, N25) - 1) -> 35
A26: 25 | B26: =IF(DATA_IMPORT!A26="", "", DATA_IMPORT!A26) | C26: =IF(DATA_IMPORT!B26="", "", DATA_IMPORT!B26) | D26: Yes | N26: =$Q$4 + RAND() -> 0.51187496 | O26: =IF(N26="", "", _xlfn.RANK.EQ(N26, $N$2:$N$120) + COUNTIF($N$2:N26, N26) - 1) -> 66
A27: 26 | B27: =IF(DATA_IMPORT!A27="", "", DATA_IMPORT!A27) | C27: =IF(DATA_IMPORT!B27="", "", DATA_IMPORT!B27) | D27: Yes | N27: =$Q$4 + RAND() -> 0.14420937 | O27: =IF(N27="", "", _xlfn.RANK.EQ(N27, $N$2:$N$120) + COUNTIF($N$2:N27, N27) - 1) -> 110
A28: 27 | B28: =IF(DATA_IMPORT!A28="", "", DATA_IMPORT!A28) | C28: =IF(DATA_IMPORT!B28="", "", DATA_IMPORT!B28) | D28: Yes | N28: =$Q$4 + RAND() -> 0.14068343 | O28: =IF(N28="", "", _xlfn.RANK.EQ(N28, $N$2:$N$120) + COUNTIF($N$2:N28, N28) - 1) -> 111
A29: 28 | B29: =IF(DATA_IMPORT!A29="", "", DATA_IMPORT!A29) | C29: =IF(DATA_IMPORT!B29="", "", DATA_IMPORT!B29) | D29: Yes | N29: =$Q$4 + RAND() -> 0.060942194 | O29: =IF(N29="", "", _xlfn.RANK.EQ(N29, $N$2:$N$120) + COUNTIF($N$2:N29, N29) - 1) -> 115
A30: 29 | B30: =IF(DATA_IMPORT!A30="", "", DATA_IMPORT!A30) | C30: =IF(DATA_IMPORT!B30="", "", DATA_IMPORT!B30) | D30: Yes | N30: =$Q$4 + RAND() -> 0.31090115 | O30: =IF(N30="", "", _xlfn.RANK.EQ(N30, $N$2:$N$120) + COUNTIF($N$2:N30, N30) - 1) -> 94
A31: 30 | B31: =IF(DATA_IMPORT!A31="", "", DATA_IMPORT!A31) | C31: =IF(DATA_IMPORT!B31="", "", DATA_IMPORT!B31) | D31: Yes | N31: =$Q$4 + RAND() -> 0.72153302 | O31: =IF(N31="", "", _xlfn.RANK.EQ(N31, $N$2:$N$120) + COUNTIF($N$2:N31, N31) - 1) -> 37
A32: 31 | B32: =IF(DATA_IMPORT!A32="", "", DATA_IMPORT!A32) | C32: =IF(DATA_IMPORT!B32="", "", DATA_IMPORT!B32) | D32: Yes | N32: =$Q$4 + RAND() -> 0.49489331 | O32: =IF(N32="", "", _xlfn.RANK.EQ(N32, $N$2:$N$120) + COUNTIF($N$2:N32, N32) - 1) -> 67
A33: 32 | B33: =IF(DATA_IMPORT!A33="", "", DATA_IMPORT!A33) | C33: =IF(DATA_IMPORT!B33="", "", DATA_IMPORT!B33) | D33: Yes | N33: =$Q$4 + RAND() -> 0.48402427 | O33: =IF(N33="", "", _xlfn.RANK.EQ(N33, $N$2:$N$120) + COUNTIF($N$2:N33, N33) - 1) -> 69
A34: 33 | B34: =IF(DATA_IMPORT!A34="", "", DATA_IMPORT!A34) | C34: =IF(DATA_IMPORT!B34="", "", DATA_IMPORT!B34) | D34: Yes | N34: =$Q$4 + RAND() -> 0.029467787 | O34: =IF(N34="", "", _xlfn.RANK.EQ(N34, $N$2:$N$120) + COUNTIF($N$2:N34, N34) - 1) -> 118
A35: 34 | B35: =IF(DATA_IMPORT!A35="", "", DATA_IMPORT!A35) | C35: =IF(DATA_IMPORT!B35="", "", DATA_IMPORT!B35) | D35: Yes | N35: =$Q$4 + RAND() -> 0.85914397 | O35: =IF(N35="", "", _xlfn.RANK.EQ(N35, $N$2:$N$120) + COUNTIF($N$2:N35, N35) - 1) -> 14
... A61: 60 | B61: =IF(DATA_IMPORT!A61="", "", DATA_IMPORT!A61) | C61: =IF(DATA_IMPORT!B61="", "", DATA_IMPORT!B61) | D61: Yes | N61: =$Q$4 + RAND() -> 0.49479213 | O61: =IF(N61="", "", _xlfn.RANK.EQ(N61, $N$2:$N$120) + COUNTIF($N$2:N61, N61) - 1) -> 68
A62: 61 | B62: =IF(DATA_IMPORT!A62="", "", DATA_IMPORT!A62) | C62: =IF(DATA_IMPORT!B62="", "", DATA_IMPORT!B62) | N62: =$Q$4 + RAND() -> 0.19846 | O62: =IF(N62="", "", _xlfn.RANK.EQ(N62, $N$2:$N$120) + COUNTIF($N$2:N62, N62) - 1) -> 104
A63: 62 | B63: =IF(DATA_IMPORT!A63="", "", DATA_IMPORT!A63) | C63: =IF(DATA_IMPORT!B63="", "", DATA_IMPORT!B63) | N63: =$Q$4 + RAND() -> 0.56697864 | O63: =IF(N63="", "", _xlfn.RANK.EQ(N63, $N$2:$N$120) + COUNTIF($N$2:N63, N63) - 1) -> 57
A64: 63 | B64: =IF(DATA_IMPORT!A64="", "", DATA_IMPORT!A64) | C64: =IF(DATA_IMPORT!B64="", "", DATA_IMPORT!B64) | N64: =$Q$4 + RAND() -> 0.39555874 | O64: =IF(N64="", "", _xlfn.RANK.EQ(N64, $N$2:$N$120) + COUNTIF($N$2:N64, N64) - 1) -> 81
A65: 64 | B65: =IF(DATA_IMPORT!A65="", "", DATA_IMPORT!A65) | C65: =IF(DATA_IMPORT!B65="", "", DATA_IMPORT!B65) | N65: =$Q$4 + RAND() -> 0.65634673 | O65: =IF(N65="", "", _xlfn.RANK.EQ(N65, $N$2:$N$120) + COUNTIF($N$2:N65, N65) - 1) -> 42
...

Sheet DAY 1 SCORES
B1: DAY 1 SCORES
B2: SEARCH
A3: ID | B3: NAME | C3: ZONE | D3: LENGTH | E3: SPECIES | F3: FISH COUNT | G3: BIGGEST FISH | H3: POINTS | I3: MASTER SCORE
A4: 1 | B4: =IF(DATA_IMPORT!A2="", "", DATA_IMPORT!A2) | C4: =IF(DATA_IMPORT!C2="", "", DATA_IMPORT!C2) | H4: =IF(D4=0, COUNTIF($C$4:$C$123, C4), COUNTIFS($C$4:$C$123, C4, $I$4:$I$123, ">"&I4) + 1) -> 120 | I4: =D4 + (F4/1000) + (G4/1000000) + (E4/1000000000) + (A4/100000000000) -> 1e-11 | J4: =C4 & (COUNTIFS($C$4:$C$123, C4, $H$4:$H$123, "<"&H4) + COUNTIFS($C$4:C4, C4, $H$4:H4, H4)) -> 1 | K4: =D4 & "/" & F4 & "/" & G4 & "/" & E4 -> /// | T4: =_xlfn.XLOOKUP(B4, REGISTRATION!B:B, REGISTRATION!C:C, "No Team")
A5: 2 | B5: =IF(DATA_IMPORT!A3="", "", DATA_IMPORT!A3) | C5: =IF(DATA_IMPORT!C3="", "", DATA_IMPORT!C3) | H5: =IF(D5=0, COUNTIF($C$4:$C$123, C5), COUNTIFS($C$4:$C$123, C5, $I$4:$I$123, ">"&I5) + 1) -> 120 | I5: =D5 + (F5/1000) + (G5/1000000) + (E5/1000000000) + (A5/100000000000) -> 2e-11 | J5: =C5 & (COUNTIFS($C$4:$C$123, C5, $H$4:$H$123, "<"&H5) + COUNTIFS($C$4:C5, C5, $H$4:H5, H5)) -> 2 | K5: =D5 & "/" & F5 & "/" & G5 & "/" & E5 -> /// | T5: =_xlfn.XLOOKUP(B5, REGISTRATION!B:B, REGISTRATION!C:C, "No Team")
A6: 3 | B6: =IF(DATA_IMPORT!A4="", "", DATA_IMPORT!A4) | C6: =IF(DATA_IMPORT!C4="", "", DATA_IMPORT!C4) | H6: =IF(D6=0, COUNTIF($C$4:$C$123, C6), COUNTIFS($C$4:$C$123, C6, $I$4:$I$123, ">"&I6) + 1) -> 120 | I6: =D6 + (F6/1000) + (G6/1000000) + (E6/1000000000) + (A6/100000000000) -> 3e-11 | J6: =C6 & (COUNTIFS($C$4:$C$123, C6, $H$4:$H$123, "<"&H6) + COUNTIFS($C$4:C6, C6, $H$4:H6, H6)) -> 3 | K6: =D6 & "/" & F6 & "/" & G6 & "/" & E6 -> /// | T6: =_xlfn.XLOOKUP(B6, REGISTRATION!B:B, REGISTRATION!C:C, "No Team")
A7: 4 | B7: =IF(DATA_IMPORT!A5="", "", DATA_IMPORT!A5) | C7: =IF(DATA_IMPORT!C5="", "", DATA_IMPORT!C5) | H7: =IF(D7=0, COUNTIF($C$4:$C$123, C7), COUNTIFS($C$4:$C$123, C7, $I$4:$I$123, ">"&I7) + 1) -> 120 | I7: =D7 + (F7/1000) + (G7/1000000) + (E7/1000000000) + (A7/100000000000) -> 4e-11 | J7: =C7 & (COUNTIFS($C$4:$C$123, C7, $H$4:$H$123, "<"&H7) + COUNTIFS($C$4:C7, C7, $H$4:H7, H7)) -> 4 | K7: =D7 & "/" & F7 & "/" & G7 & "/" & E7 -> /// | T7: =_xlfn.XLOOKUP(B7, REGISTRATION!B:B, REGISTRATION!C:C, "No Team")
A8: 5 | B8: =IF(DATA_IMPORT!A6="", "", DATA_IMPORT!A6) | C8: =IF(DATA_IMPORT!C6="", "", DATA_IMPORT!C6) | H8: =IF(D8=0, COUNTIF($C$4:$C$123, C8), COUNTIFS($C$4:$C$123, C8, $I$4:$I$123, ">"&I8) + 1) -> 120 | I8: =D8 + (F8/1000) + (G8/1000000) + (E8/1000000000) + (A8/100000000000) -> 5e-11 | J8: =C8 & (COUNTIFS($C$4:$C$123, C8, $H$4:$H$123, "<"&H8) + COUNTIFS($C$4:C8, C8, $H$4:H8, H8)) -> 5 | K8: =D8 & "/" & F8 & "/" & G8 & "/" & E8 -> /// | T8: =_xlfn.XLOOKUP(B8, REGISTRATION!B:B, REGISTRATION!C:C, "No Team")
A9: 6 | B9: =IF(DATA_IMPORT!A7="", "", DATA_IMPORT!A7) | C9: =IF(DATA_IMPORT!C7="", "", DATA_IMPORT!C7) | H9: =IF(D9=0, COUNTIF($C$4:$C$123, C9), COUNTIFS($C$4:$C$123, C9, $I$4:$I$123, ">"&I9) + 1) -> 120 | I9: =D9 + (F9/1000) + (G9/1000000) + (E9/1000000000) + (A9/100000000000) -> 6e-11 | J9: =C9 & (COUNTIFS($C$4:$C$123, C9, $H$4:$H$123, "<"&H9) + COUNTIFS($C$4:C9, C9, $H$4:H9, H9)) -> 6 | K9: =D9 & "/" & F9 & "/" & G9 & "/" & E9 -> /// | T9: =_xlfn.XLOOKUP(B9, REGISTRATION!B:B, REGISTRATION!C:C, "No Team")
A10: 7 | B10: =IF(DATA_IMPORT!A8="", "", DATA_IMPORT!A8) | C10: =IF(DATA_IMPORT!C8="", "", DATA_IMPORT!C8) | H10: =IF(D10=0, COUNTIF($C$4:$C$123, C10), COUNTIFS($C$4:$C$123, C10, $I$4:$I$123, ">"&I10) + 1) -> 120 | I10: =D10 + (F10/1000) + (G10/1000000) + (E10/1000000000) + (A10/100000000000) -> 7e-11 | J10: =C10 & (COUNTIFS($C$4:$C$123, C10, $H$4:$H$123, "<"&H10) + COUNTIFS($C$4:C10, C10, $H$4:H10, H10)) -> 7 | K10: =D10 & "/" & F10 & "/" & G10 & "/" & E10 -> /// | T10: =_xlfn.XLOOKUP(B10, REGISTRATION!B:B, REGISTRATION!C:C, "No Team")
A11: 8 | B11: =IF(DATA_IMPORT!A9="", "", DATA_IMPORT!A9) | C11: =IF(DATA_IMPORT!C9="", "", DATA_IMPORT!C9) | H11: =IF(D11=0, COUNTIF($C$4:$C$123, C11), COUNTIFS($C$4:$C$123, C11, $I$4:$I$123, ">"&I11) + 1) -> 120 | I11: =D11 + (F11/1000) + (G11/1000000) + (E11/1000000000) + (A11/100000000000) -> 8e-11 | J11: =C11 & (COUNTIFS($C$4:$C$123, C11, $H$4:$H$123, "<"&H11) + COUNTIFS($C$4:C11, C11, $H$4:H11, H11)) -> 8 | K11: =D11 & "/" & F11 & "/" & G11 & "/" & E11 -> /// | T11: =_xlfn.XLOOKUP(B11, REGISTRATION!B:B, REGISTRATION!C:C, "No Team")
A12: 9 | B12: =IF(DATA_IMPORT!A10="", "", DATA_IMPORT!A10) | C12: =IF(DATA_IMPORT!C10="", "", DATA_IMPORT!C10) | H12: =IF(D12=0, COUNTIF($C$4:$C$123, C12), COUNTIFS($C$4:$C$123, C12, $I$4:$I$123, ">"&I12) + 1) -> 120 | I12: =D12 + (F12/1000) + (G12/1000000) + (E12/1000000000) + (A12/100000000000) -> 9e-11 | J12: =C12 & (COUNTIFS($C$4:$C$123, C12, $H$4:$H$123, "<"&H12) + COUNTIFS($C$4:C12, C12, $H$4:H12, H12)) -> 9 | K12: =D12 & "/" & F12 & "/" & G12 & "/" & E12 -> /// | T12: =_xlfn.XLOOKUP(B12, REGISTRATION!B:B, REGISTRATION!C:C, "No Team")
A13: 10 | B13: =IF(DATA_IMPORT!A11="", "", DATA_IMPORT!A11) | C13: =IF(DATA_IMPORT!C11="", "", DATA_IMPORT!C11) | H13: =IF(D13=0, COUNTIF($C$4:$C$123, C13), COUNTIFS($C$4:$C$123, C13, $I$4:$I$123, ">"&I13) + 1) -> 120 | I13: =D13 + (F13/1000) + (G13/1000000) + (E13/1000000000) + (A13/100000000000) -> 1e-10 | J13: =C13 & (COUNTIFS($C$4:$C$123, C13, $H$4:$H$123, "<"&H13) + COUNTIFS($C$4:C13, C13, $H$4:H13, H13)) -> 10 | K13: =D13 & "/" & F13 & "/" & G13 & "/" & E13 -> /// | T13: =_xlfn.XLOOKUP(B13, REGISTRATION!B:B, REGISTRATION!C:C, "No Team")
A14: 11 | B14: =IF(DATA_IMPORT!A12="", "", DATA_IMPORT!A12) | C14: =IF(DATA_IMPORT!C12="", "", DATA_IMPORT!C12) | H14: =IF(D14=0, COUNTIF($C$4:$C$123, C14), COUNTIFS($C$4:$C$123, C14, $I$4:$I$123, ">"&I14) + 1) -> 120 | I14: =D14 + (F14/1000) + (G14/1000000) + (E14/1000000000) + (A14/100000000000) -> 1.1e-10 | J14: =C14 & (COUNTIFS($C$4:$C$123, C14, $H$4:$H$123, "<"&H14) + COUNTIFS($C$4:C14, C14, $H$4:H14, H14)) -> 11 | K14: =D14 & "/" & F14 & "/" & G14 & "/" & E14 -> /// | T14: =_xlfn.XLOOKUP(B14, REGISTRATION!B:B, REGISTRATION!C:C, "No Team")
A15: 12 | B15: =IF(DATA_IMPORT!A13="", "", DATA_IMPORT!A13) | C15: =IF(DATA_IMPORT!C13="", "", DATA_IMPORT!C13) | H15: =IF(D15=0, COUNTIF($C$4:$C$123, C15), COUNTIFS($C$4:$C$123, C15, $I$4:$I$123, ">"&I15) + 1) -> 120 | I15: =D15 + (F15/1000) + (G15/1000000) + (E15/1000000000) + (A15/100000000000) -> 1.2e-10 | J15: =C15 & (COUNTIFS($C$4:$C$123, C15, $H$4:$H$123, "<"&H15) + COUNTIFS($C$4:C15, C15, $H$4:H15, H15)) -> 12 | K15: =D15 & "/" & F15 & "/" & G15 & "/" & E15 -> /// | T15: =_xlfn.XLOOKUP(B15, REGISTRATION!B:B, REGISTRATION!C:C, "No Team")
A16: 13 | B16: =IF(DATA_IMPORT!A14="", "", DATA_IMPORT!A14) | C16: =IF(DATA_IMPORT!C14="", "", DATA_IMPORT!C14) | H16: =IF(D16=0, COUNTIF($C$4:$C$123, C16), COUNTIFS($C$4:$C$123, C16, $I$4:$I$123, ">"&I16) + 1) -> 120 | I16: =D16 + (F16/1000) + (G16/1000000) + (E16/1000000000) + (A16/100000000000) -> 1.3e-10 | J16: =C16 & (COUNTIFS($C$4:$C$123, C16, $H$4:$H$123, "<"&H16) + COUNTIFS($C$4:C16, C16, $H$4:H16, H16)) -> 13 | K16: =D16 & "/" & F16 & "/" & G16 & "/" & E16 -> /// | T16: =_xlfn.XLOOKUP(B16, REGISTRATION!B:B, REGISTRATION!C:C, "No Team")
A17: 14 | B17: =IF(DATA_IMPORT!A15="", "", DATA_IMPORT!A15) | C17: =IF(DATA_IMPORT!C15="", "", DATA_IMPORT!C15) | H17: =IF(D17=0, COUNTIF($C$4:$C$123, C17), COUNTIFS($C$4:$C$123, C17, $I$4:$I$123, ">"&I17) + 1) -> 120 | I17: =D17 + (F17/1000) + (G17/1000000) + (E17/1000000000) + (A17/100000000000) -> 1.4e-10 | J17: =C17 & (COUNTIFS($C$4:$C$123, C17, $H$4:$H$123, "<"&H17) + COUNTIFS($C$4:C17, C17, $H$4:H17, H17)) -> 14 | K17: =D17 & "/" & F17 & "/" & G17 & "/" & E17 -> /// | T17: =_xlfn.XLOOKUP(B17, REGISTRATION!B:B, REGISTRATION!C:C, "No Team") | U17: =COUNTIF('DAY 1 SCORES'!$C$4:$C$123, "?*") -> 0
A18: 15 | B18: =IF(DATA_IMPORT!A16="", "", DATA_IMPORT!A16) | C18: =IF(DATA_IMPORT!C16="", "", DATA_IMPORT!C16) | H18: =IF(D18=0, COUNTIF($C$4:$C$123, C18), COUNTIFS($C$4:$C$123, C18, $I$4:$I$123, ">"&I18) + 1) -> 120 | I18: =D18 + (F18/1000) + (G18/1000000) + (E18/1000000000) + (A18/100000000000) -> 1.5e-10 | J18: =C18 & (COUNTIFS($C$4:$C$123, C18, $H$4:$H$123, "<"&H18) + COUNTIFS($C$4:C18, C18, $H$4:H18, H18)) -> 15 | K18: =D18 & "/" & F18 & "/" & G18 & "/" & E18 -> /// | T18: =_xlfn.XLOOKUP(B18, REGISTRATION!B:B, REGISTRATION!C:C, "No Team")
A19: 16 | B19: =IF(DATA_IMPORT!A17="", "", DATA_IMPORT!A17) | C19: =IF(DATA_IMPORT!C17="", "", DATA_IMPORT!C17) | H19: =IF(D19=0, COUNTIF($C$4:$C$123, C19), COUNTIFS($C$4:$C$123, C19, $I$4:$I$123, ">"&I19) + 1) -> 120 | I19: =D19 + (F19/1000) + (G19/1000000) + (E19/1000000000) + (A19/100000000000) -> 1.6e-10 | J19: =C19 & (COUNTIFS($C$4:$C$123, C19, $H$4:$H$123, "<"&H19) + COUNTIFS($C$4:C19, C19, $H$4:H19, H19)) -> 16 | K19: =D19 & "/" & F19 & "/" & G19 & "/" & E19 -> /// | T19: =_xlfn.XLOOKUP(B19, REGISTRATION!B:B, REGISTRATION!C:C, "No Team")
A20: 17 | B20: =IF(DATA_IMPORT!A18="", "", DATA_IMPORT!A18) | C20: =IF(DATA_IMPORT!C18="", "", DATA_IMPORT!C18) | H20: =IF(D20=0, COUNTIF($C$4:$C$123, C20), COUNTIFS($C$4:$C$123, C20, $I$4:$I$123, ">"&I20) + 1) -> 120 | I20: =D20 + (F20/1000) + (G20/1000000) + (E20/1000000000) + (A20/100000000000) -> 1.7e-10 | J20: =C20 & (COUNTIFS($C$4:$C$123, C20, $H$4:$H$123, "<"&H20) + COUNTIFS($C$4:C20, C20, $H$4:H20, H20)) -> 17 | K20: =D20 & "/" & F20 & "/" & G20 & "/" & E20 -> /// | T20: =_xlfn.XLOOKUP(B20, REGISTRATION!B:B, REGISTRATION!C:C, "No Team")
A21: 18 | B21: =IF(DATA_IMPORT!A19="", "", DATA_IMPORT!A19) | C21: =IF(DATA_IMPORT!C19="", "", DATA_IMPORT!C19) | H21: =IF(D21=0, COUNTIF($C$4:$C$123, C21), COUNTIFS($C$4:$C$123, C21, $I$4:$I$123, ">"&I21) + 1) -> 120 | I21: =D21 + (F21/1000) + (G21/1000000) + (E21/1000000000) + (A21/100000000000) -> 1.8e-10 | J21: =C21 & (COUNTIFS($C$4:$C$123, C21, $H$4:$H$123, "<"&H21) + COUNTIFS($C$4:C21, C21, $H$4:H21, H21)) -> 18 | K21: =D21 & "/" & F21 & "/" & G21 & "/" & E21 -> /// | T21: =_xlfn.XLOOKUP(B21, REGISTRATION!B:B, REGISTRATION!C:C, "No Team")
A22: 19 | B22: =IF(DATA_IMPORT!A20="", "", DATA_IMPORT!A20) | C22: =IF(DATA_IMPORT!C20="", "", DATA_IMPORT!C20) | H22: =IF(D22=0, COUNTIF($C$4:$C$123, C22), COUNTIFS($C$4:$C$123, C22, $I$4:$I$123, ">"&I22) + 1) -> 120 | I22: =D22 + (F22/1000) + (G22/1000000) + (E22/1000000000) + (A22/100000000000) -> 1.9e-10 | J22: =C22 & (COUNTIFS($C$4:$C$123, C22, $H$4:$H$123, "<"&H22) + COUNTIFS($C$4:C22, C22, $H$4:H22, H22)) -> 19 | K22: =D22 & "/" & F22 & "/" & G22 & "/" & E22 -> /// | T22: =_xlfn.XLOOKUP(B22, REGISTRATION!B:B, REGISTRATION!C:C, "No Team")
A23: 20 | B23: =IF(DATA_IMPORT!A21="", "", DATA_IMPORT!A21) | C23: =IF(DATA_IMPORT!C21="", "", DATA_IMPORT!C21) | H23: =IF(D23=0, COUNTIF($C$4:$C$123, C23), COUNTIFS($C$4:$C$123, C23, $I$4:$I$123, ">"&I23) + 1) -> 120 | I23: =D23 + (F23/1000) + (G23/1000000) + (E23/1000000000) + (A23/100000000000) -> 2e-10 | J23: =C23 & (COUNTIFS($C$4:$C$123, C23, $H$4:$H$123, "<"&H23) + COUNTIFS($C$4:C23, C23, $H$4:H23, H23)) -> 20 | K23: =D23 & "/" & F23 & "/" & G23 & "/" & E23 -> /// | T23: =_xlfn.XLOOKUP(B23, REGISTRATION!B:B, REGISTRATION!C:C, "No Team")
A24: 21 | B24: =IF(DATA_IMPORT!A22="", "", DATA_IMPORT!A22) | C24: =IF(DATA_IMPORT!C22="", "", DATA_IMPORT!C22) | H24: =IF(D24=0, COUNTIF($C$4:$C$123, C24), COUNTIFS($C$4:$C$123, C24, $I$4:$I$123, ">"&I24) + 1) -> 120 | I24: =D24 + (F24/1000) + (G24/1000000) + (E24/1000000000) + (A24/100000000000) -> 2.1e-10 | J24: =C24 & (COUNTIFS($C$4:$C$123, C24, $H$4:$H$123, "<"&H24) + COUNTIFS($C$4:C24, C24, $H$4:H24, H24)) -> 21 | K24: =D24 & "/" & F24 & "/" & G24 & "/" & E24 -> /// | T24: =_xlfn.XLOOKUP(B24, REGISTRATION!B:B, REGISTRATION!C:C, "No Team")
A25: 22 | B25: =IF(DATA_IMPORT!A23="", "", DATA_IMPORT!A23) | C25: =IF(DATA_IMPORT!C23="", "", DATA_IMPORT!C23) | H25: =IF(D25=0, COUNTIF($C$4:$C$123, C25), COUNTIFS($C$4:$C$123, C25, $I$4:$I$123, ">"&I25) + 1) -> 120 | I25: =D25 + (F25/1000) + (G25/1000000) + (E25/1000000000) + (A25/100000000000) -> 2.2e-10 | J25: =C25 & (COUNTIFS($C$4:$C$123, C25, $H$4:$H$123, "<"&H25) + COUNTIFS($C$4:C25, C25, $H$4:H25, H25)) -> 22 | K25: =D25 & "/" & F25 & "/" & G25 & "/" & E25 -> /// | T25: =_xlfn.XLOOKUP(B25, REGISTRATION!B:B, REGISTRATION!C:C, "No Team")
A26: 23 | B26: =IF(DATA_IMPORT!A24="", "", DATA_IMPORT!A24) | C26: =IF(DATA_IMPORT!C24="", "", DATA_IMPORT!C24) | H26: =IF(D26=0, COUNTIF($C$4:$C$123, C26), COUNTIFS($C$4:$C$123, C26, $I$4:$I$123, ">"&I26) + 1) -> 120 | I26: =D26 + (F26/1000) + (G26/1000000) + (E26/1000000000) + (A26/100000000000) -> 2.3e-10 | J26: =C26 & (COUNTIFS($C$4:$C$123, C26, $H$4:$H$123, "<"&H26) + COUNTIFS($C$4:C26, C26, $H$4:H26, H26)) -> 23 | K26: =D26 & "/" & F26 & "/" & G26 & "/" & E26 -> /// | T26: =_xlfn.XLOOKUP(B26, REGISTRATION!B:B, REGISTRATION!C:C, "No Team")
A27: 24 | B27: =IF(DATA_IMPORT!A25="", "", DATA_IMPORT!A25) | C27: =IF(DATA_IMPORT!C25="", "", DATA_IMPORT!C25) | H27: =IF(D27=0, COUNTIF($C$4:$C$123, C27), COUNTIFS($C$4:$C$123, C27, $I$4:$I$123, ">"&I27) + 1) -> 120 | I27: =D27 + (F27/1000) + (G27/1000000) + (E27/1000000000) + (A27/100000000000) -> 2.4e-10 | J27: =C27 & (COUNTIFS($C$4:$C$123, C27, $H$4:$H$123, "<"&H27) + COUNTIFS($C$4:C27, C27, $H$4:H27, H27)) -> 24 | K27: =D27 & "/" & F27 & "/" & G27 & "/" & E27 -> /// | T27: =_xlfn.XLOOKUP(B27, REGISTRATION!B:B, REGISTRATION!C:C, "No Team")
A28: 25 | B28: =IF(DATA_IMPORT!A26="", "", DATA_IMPORT!A26) | C28: =IF(DATA_IMPORT!C26="", "", DATA_IMPORT!C26) | H28: =IF(D28=0, COUNTIF($C$4:$C$123, C28), COUNTIFS($C$4:$C$123, C28, $I$4:$I$123, ">"&I28) + 1) -> 120 | I28: =D28 + (F28/1000) + (G28/1000000) + (E28/1000000000) + (A28/100000000000) -> 2.5e-10 | J28: =C28 & (COUNTIFS($C$4:$C$123, C28, $H$4:$H$123, "<"&H28) + COUNTIFS($C$4:C28, C28, $H$4:H28, H28)) -> 25 | K28: =D28 & "/" & F28 & "/" & G28 & "/" & E28 -> /// | T28: =_xlfn.XLOOKUP(B28, REGISTRATION!B:B, REGISTRATION!C:C, "No Team")
A29: 26 | B29: =IF(DATA_IMPORT!A27="", "", DATA_IMPORT!A27) | C29: =IF(DATA_IMPORT!C27="", "", DATA_IMPORT!C27) | H29: =IF(D29=0, COUNTIF($C$4:$C$123, C29), COUNTIFS($C$4:$C$123, C29, $I$4:$I$123, ">"&I29) + 1) -> 120 | I29: =D29 + (F29/1000) + (G29/1000000) + (E29/1000000000) + (A29/100000000000) -> 2.6e-10 | J29: =C29 & (COUNTIFS($C$4:$C$123, C29, $H$4:$H$123, "<"&H29) + COUNTIFS($C$4:C29, C29, $H$4:H29, H29)) -> 26 | K29: =D29 & "/" & F29 & "/" & G29 & "/" & E29 -> /// | T29: =_xlfn.XLOOKUP(B29, REGISTRATION!B:B, REGISTRATION!C:C, "No Team")
... A40: 37 | B40: =IF(DATA_IMPORT!A38="", "", DATA_IMPORT!A38) | C40: =IF(DATA_IMPORT!C38="", "", DATA_IMPORT!C38) | H40: =IF(D40=0, COUNTIF($C$4:$C$123, C40), COUNTIFS($C$4:$C$123, C40, $I$4:$I$123, ">"&I40) + 1) -> 120 | I40: =D40 + (F40/1000) + (G40/1000000) + (E40/1000000000) + (A40/100000000000) -> 3.7e-10 | J40: =C40 & (COUNTIFS($C$4:$C$123, C40, $H$4:$H$123, "<"&H40) + COUNTIFS($C$4:C40, C40, $H$4:H40, H40)) -> 37 | K40: =D40 & "/" & F40 & "/" & G40 & "/" & E40 -> /// | T40: =_xlfn.XLOOKUP(B40, REGISTRATION!B:B, REGISTRATION!C:C, "No Team")
A41: 38 | B41: =IF(DATA_IMPORT!A39="", "", DATA_IMPORT!A39) | C41: =IF(DATA_IMPORT!C39="", "", DATA_IMPORT!C39) | H41: =IF(D41=0, COUNTIF($C$4:$C$123, C41), COUNTIFS($C$4:$C$123, C41, $I$4:$I$123, ">"&I41) + 1) -> 120 | I41: =D41 + (F41/1000) + (G41/1000000) + (E41/1000000000) + (A41/100000000000) -> 3.8e-10 | J41: =C41 & (COUNTIFS($C$4:$C$123, C41, $H$4:$H$123, "<"&H41) + COUNTIFS($C$4:C41, C41, $H$4:H41, H41)) -> 38 | K41: =D41 & "/" & F41 & "/" & G41 & "/" & E41 -> ///
A42: 39 | B42: =IF(DATA_IMPORT!A40="", "", DATA_IMPORT!A40) | C42: =IF(DATA_IMPORT!C40="", "", DATA_IMPORT!C40) | H42: =IF(D42=0, COUNTIF($C$4:$C$123, C42), COUNTIFS($C$4:$C$123, C42, $I$4:$I$123, ">"&I42) + 1) -> 120 | I42: =D42 + (F42/1000) + (G42/1000000) + (E42/1000000000) + (A42/100000000000) -> 3.9e-10 | J42: =C42 & (COUNTIFS($C$4:$C$123, C42, $H$4:$H$123, "<"&H42) + COUNTIFS($C$4:C42, C42, $H$4:H42, H42)) -> 39 | K42: =D42 & "/" & F42 & "/" & G42 & "/" & E42 -> ///
A43: 40 | B43: =IF(DATA_IMPORT!A41="", "", DATA_IMPORT!A41) | C43: =IF(DATA_IMPORT!C41="", "", DATA_IMPORT!C41) | H43: =IF(D43=0, COUNTIF($C$4:$C$123, C43), COUNTIFS($C$4:$C$123, C43, $I$4:$I$123, ">"&I43) + 1) -> 120 | I43: =D43 + (F43/1000) + (G43/1000000) + (E43/1000000000) + (A43/100000000000) -> 4e-10 | J43: =C43 & (COUNTIFS($C$4:$C$123, C43, $H$4:$H$123, "<"&H43) + COUNTIFS($C$4:C43, C43, $H$4:H43, H43)) -> 40 | K43: =D43 & "/" & F43 & "/" & G43 & "/" & E43 -> ///
A44: 41 | B44: =IF(DATA_IMPORT!A42="", "", DATA_IMPORT!A42) | C44: =IF(DATA_IMPORT!C42="", "", DATA_IMPORT!C42) | H44: =IF(D44=0, COUNTIF($C$4:$C$123, C44), COUNTIFS($C$4:$C$123, C44, $I$4:$I$123, ">"&I44) + 1) -> 120 | I44: =D44 + (F44/1000) + (G44/1000000) + (E44/1000000000) + (A44/100000000000) -> 4.1e-10 | J44: =C44 & (COUNTIFS($C$4:$C$123, C44, $H$4:$H$123, "<"&H44) + COUNTIFS($C$4:C44, C44, $H$4:H44, H44)) -> 41 | K44: =D44 & "/" & F44 & "/" & G44 & "/" & E44 -> ///
A45: 42 | B45: =IF(DATA_IMPORT!A43="", "", DATA_IMPORT!A43) | C45: =IF(DATA_IMPORT!C43="", "", DATA_IMPORT!C43) | H45: =IF(D45=0, COUNTIF($C$4:$C$123, C45), COUNTIFS($C$4:$C$123, C45, $I$4:$I$123, ">"&I45) + 1) -> 120 | I45: =D45 + (F45/1000) + (G45/1000000) + (E45/1000000000) + (A45/100000000000) -> 4.2e-10 | J45: =C45 & (COUNTIFS($C$4:$C$123, C45, $H$4:$H$123, "<"&H45) + COUNTIFS($C$4:C45, C45, $H$4:H45, H45)) -> 42 | K45: =D45 & "/" & F45 & "/" & G45 & "/" & E45 -> ///
A46: 43 | B46: =IF(DATA_IMPORT!A44="", "", DATA_IMPORT!A44) | C46: =IF(DATA_IMPORT!C44="", "", DATA_IMPORT!C44) | H46: =IF(D46=0, COUNTIF($C$4:$C$123, C46), COUNTIFS($C$4:$C$123, C46, $I$4:$I$123, ">"&I46) + 1) -> 120 | I46: =D46 + (F46/1000) + (G46/1000000) + (E46/1000000000) + (A46/100000000000) -> 4.3e-10 | J46: =C46 & (COUNTIFS($C$4:$C$123, C46, $H$4:$H$123, "<"&H46) + COUNTIFS($C$4:C46, C46, $H$4:H46, H46)) -> 43 | K46: =D46 & "/" & F46 & "/" & G46 & "/" & E46 -> ///
A47: 44 | B47: =IF(DATA_IMPORT!A45="", "", DATA_IMPORT!A45) | C47: =IF(DATA_IMPORT!C45="", "", DATA_IMPORT!C45) | H47: =IF(D47=0, COUNTIF($C$4:$C$123, C47), COUNTIFS($C$4:$C$123, C47, $I$4:$I$123, ">"&I47) + 1) -> 120 | I47: =D47 + (F47/1000) + (G47/1000000) + (E47/1000000000) + (A47/100000000000) -> 4.4e-10 | J47: =C47 & (COUNTIFS($C$4:$C$123, C47, $H$4:$H$123, "<"&H47) + COUNTIFS($C$4:C47, C47, $H$4:H47, H47)) -> 44 | K47: =D47 & "/" & F47 & "/" & G47 & "/" & E47 -> ///
A48: 45 | B48: =IF(DATA_IMPORT!A46="", "", DATA_IMPORT!A46) | C48: =IF(DATA_IMPORT!C46="", "", DATA_IMPORT!C46) | H48: =IF(D48=0, COUNTIF($C$4:$C$123, C48), COUNTIFS($C$4:$C$123, C48, $I$4:$I$123, ">"&I48) + 1) -> 120 | I48: =D48 + (F48/1000) + (G48/1000000) + (E48/1000000000) + (A48/100000000000) -> 4.5e-10 | J48: =C48 & (COUNTIFS($C$4:$C$123, C48, $H$4:$H$123, "<"&H48) + COUNTIFS($C$4:C48, C48, $H$4:H48, H48)) -> 45 | K48: =D48 & "/" & F48 & "/" & G48 & "/" & E48 -> ///
A49: 46 | B49: =IF(DATA_IMPORT!A47="", "", DATA_IMPORT!A47) | C49: =IF(DATA_IMPORT!C47="", "", DATA_IMPORT!C47) | H49: =IF(D49=0, COUNTIF($C$4:$C$123, C49), COUNTIFS($C$4:$C$123, C49, $I$4:$I$123, ">"&I49) + 1) -> 120 | I49: =D49 + (F49/1000) + (G49/1000000) + (E49/1000000000) + (A49/100000000000) -> 4.6e-10 | J49: =C49 & (COUNTIFS($C$4:$C$123, C49, $H$4:$H$123, "<"&H49) + COUNTIFS($C$4:C49, C49, $H$4:H49, H49)) -> 46 | K49: =D49 & "/" & F49 & "/" & G49 & "/" & E49 -> ///
A50: 47 | B50: =IF(DATA_IMPORT!A48="", "", DATA_IMPORT!A48) | C50: =IF(DATA_IMPORT!C48="", "", DATA_IMPORT!C48) | H50: =IF(D50=0, COUNTIF($C$4:$C$123, C50), COUNTIFS($C$4:$C$123, C50, $I$4:$I$123, ">"&I50) + 1) -> 120 | I50: =D50 + (F50/1000) + (G50/1000000) + (E50/1000000000) + (A50/100000000000) -> 4.7e-10 | J50: =C50 & (COUNTIFS($C$4:$C$123, C50, $H$4:$H$123, "<"&H50) + COUNTIFS($C$4:C50, C50, $H$4:H50, H50)) -> 47 | K50: =D50 & "/" & F50 & "/" & G50 & "/" & E50 -> ///
...

Sheet DAY 2 SCORES
B1: DAY 2 SCORES
B2: SEARCH
A3: ID | B3: NAME | C3: ZONE | D3: LENGTH | E3: SPECIES | F3: FISH COUNT | G3: BIGGEST FISH | H3: POINTS | I3: MASTER SCORE | J3: =TRIM(C3) & (COUNTIFS($C$4:$C$123, C3, $I$4:$I$123, ">"&I3) + 1) -> ZONE1
A4: 1 | B4: =IF(DATA_IMPORT!A2="", "", DATA_IMPORT!A2) | C4: =IF(DATA_IMPORT!D2="", "", DATA_IMPORT!D2) | H4: =IF(D4=0, COUNTIF($C$4:$C$123, C4), COUNTIFS($C$4:$C$123, C4, $I$4:$I$123, ">"&I4) + 1) -> 120 | I4: =D4 + (F4/1000) + (G4/1000000) + (E4/1000000000) + (A4/100000000000) -> 1e-11 | J4: =TRIM(C4) & (COUNTIFS($C$4:$C$123, C4, $I$4:$I$123, ">"&I4) + 1) -> 120 | K4: =D4 & "/" & F4 & "/" & G4 & "/" & E4 -> /// | AA4: =_xlfn.XLOOKUP(B4, REGISTRATION!B:B, REGISTRATION!C:C, "No Team")
A5: 2 | B5: =IF(DATA_IMPORT!A3="", "", DATA_IMPORT!A3) | C5: =IF(DATA_IMPORT!D3="", "", DATA_IMPORT!D3) | H5: =IF(D5=0, COUNTIF($C$4:$C$123, C5), COUNTIFS($C$4:$C$123, C5, $I$4:$I$123, ">"&I5) + 1) -> 120 | I5: =D5 + (F5/1000) + (G5/1000000) + (E5/1000000000) + (A5/100000000000) -> 2e-11 | J5: =TRIM(C5) & (COUNTIFS($C$4:$C$123, C5, $I$4:$I$123, ">"&I5) + 1) -> 119 | K5: =D5 & "/" & F5 & "/" & G5 & "/" & E5 -> /// | AA5: =_xlfn.XLOOKUP(B5, REGISTRATION!B:B, REGISTRATION!C:C, "No Team")
A6: 3 | B6: =IF(DATA_IMPORT!A4="", "", DATA_IMPORT!A4) | C6: =IF(DATA_IMPORT!D4="", "", DATA_IMPORT!D4) | H6: =IF(D6=0, COUNTIF($C$4:$C$123, C6), COUNTIFS($C$4:$C$123, C6, $I$4:$I$123, ">"&I6) + 1) -> 120 | I6: =D6 + (F6/1000) + (G6/1000000) + (E6/1000000000) + (A6/100000000000) -> 3e-11 | J6: =TRIM(C6) & (COUNTIFS($C$4:$C$123, C6, $I$4:$I$123, ">"&I6) + 1) -> 118 | K6: =D6 & "/" & F6 & "/" & G6 & "/" & E6 -> /// | AA6: =_xlfn.XLOOKUP(B6, REGISTRATION!B:B, REGISTRATION!C:C, "No Team")
A7: 4 | B7: =IF(DATA_IMPORT!A5="", "", DATA_IMPORT!A5) | C7: =IF(DATA_IMPORT!D5="", "", DATA_IMPORT!D5) | H7: =IF(D7=0, COUNTIF($C$4:$C$123, C7), COUNTIFS($C$4:$C$123, C7, $I$4:$I$123, ">"&I7) + 1) -> 120 | I7: =D7 + (F7/1000) + (G7/1000000) + (E7/1000000000) + (A7/100000000000) -> 4e-11 | J7: =TRIM(C7) & (COUNTIFS($C$4:$C$123, C7, $I$4:$I$123, ">"&I7) + 1) -> 117 | K7: =D7 & "/" & F7 & "/" & G7 & "/" & E7 -> /// | AA7: =_xlfn.XLOOKUP(B7, REGISTRATION!B:B, REGISTRATION!C:C, "No Team")
A8: 5 | B8: =IF(DATA_IMPORT!A6="", "", DATA_IMPORT!A6) | C8: =IF(DATA_IMPORT!D6="", "", DATA_IMPORT!D6) | H8: =IF(D8=0, COUNTIF($C$4:$C$123, C8), COUNTIFS($C$4:$C$123, C8, $I$4:$I$123, ">"&I8) + 1) -> 120 | I8: =D8 + (F8/1000) + (G8/1000000) + (E8/1000000000) + (A8/100000000000) -> 5e-11 | J8: =TRIM(C8) & (COUNTIFS($C$4:$C$123, C8, $I$4:$I$123, ">"&I8) + 1) -> 116 | K8: =D8 & "/" & F8 & "/" & G8 & "/" & E8 -> /// | AA8: =_xlfn.XLOOKUP(B8, REGISTRATION!B:B, REGISTRATION!C:C, "No Team")
A9: 6 | B9: =IF(DATA_IMPORT!A7="", "", DATA_IMPORT!A7) | C9: =IF(DATA_IMPORT!D7="", "", DATA_IMPORT!D7) | H9: =IF(D9=0, COUNTIF($C$4:$C$123, C9), COUNTIFS($C$4:$C$123, C9, $I$4:$I$123, ">"&I9) + 1) -> 120 | I9: =D9 + (F9/1000) + (G9/1000000) + (E9/1000000000) + (A9/100000000000) -> 6e-11 | J9: =TRIM(C9) & (COUNTIFS($C$4:$C$123, C9, $I$4:$I$123, ">"&I9) + 1) -> 115 | K9: =D9 & "/" & F9 & "/" & G9 & "/" & E9 -> /// | AA9: =_xlfn.XLOOKUP(B9, REGISTRATION!B:B, REGISTRATION!C:C, "No Team")
A10: 7 | B10: =IF(DATA_IMPORT!A8="", "", DATA_IMPORT!A8) | C10: =IF(DATA_IMPORT!D8="", "", DATA_IMPORT!D8) | H10: =IF(D10=0, COUNTIF($C$4:$C$123, C10), COUNTIFS($C$4:$C$123, C10, $I$4:$I$123, ">"&I10) + 1) -> 120 | I10: =D10 + (F10/1000) + (G10/1000000) + (E10/1000000000) + (A10/100000000000) -> 7e-11 | J10: =TRIM(C10) & (COUNTIFS($C$4:$C$123, C10, $I$4:$I$123, ">"&I10) + 1) -> 114 | K10: =D10 & "/" & F10 & "/" & G10 & "/" & E10 -> /// | AA10: =_xlfn.XLOOKUP(B10, REGISTRATION!B:B, REGISTRATION!C:C, "No Team")
A11: 8 | B11: =IF(DATA_IMPORT!A9="", "", DATA_IMPORT!A9) | C11: =IF(DATA_IMPORT!D9="", "", DATA_IMPORT!D9) | H11: =IF(D11=0, COUNTIF($C$4:$C$123, C11), COUNTIFS($C$4:$C$123, C11, $I$4:$I$123, ">"&I11) + 1) -> 120 | I11: =D11 + (F11/1000) + (G11/1000000) + (E11/1000000000) + (A11/100000000000) -> 8e-11 | J11: =TRIM(C11) & (COUNTIFS($C$4:$C$123, C11, $I$4:$I$123, ">"&I11) + 1) -> 113 | K11: =D11 & "/" & F11 & "/" & G11 & "/" & E11 -> /// | AA11: =_xlfn.XLOOKUP(B11, REGISTRATION!B:B, REGISTRATION!C:C, "No Team")
A12: 9 | B12: =IF(DATA_IMPORT!A10="", "", DATA_IMPORT!A10) | C12: =IF(DATA_IMPORT!D10="", "", DATA_IMPORT!D10) | H12: =IF(D12=0, COUNTIF($C$4:$C$123, C12), COUNTIFS($C$4:$C$123, C12, $I$4:$I$123, ">"&I12) + 1) -> 120 | I12: =D12 + (F12/1000) + (G12/1000000) + (E12/1000000000) + (A12/100000000000) -> 9e-11 | J12: =TRIM(C12) & (COUNTIFS($C$4:$C$123, C12, $I$4:$I$123, ">"&I12) + 1) -> 112 | K12: =D12 & "/" & F12 & "/" & G12 & "/" & E12 -> /// | AA12: =_xlfn.XLOOKUP(B12, REGISTRATION!B:B, REGISTRATION!C:C, "No Team")
A13: 10 | B13: =IF(DATA_IMPORT!A11="", "", DATA_IMPORT!A11) | C13: =IF(DATA_IMPORT!D11="", "", DATA_IMPORT!D11) | H13: =IF(D13=0, COUNTIF($C$4:$C$123, C13), COUNTIFS($C$4:$C$123, C13, $I$4:$I$123, ">"&I13) + 1) -> 120 | I13: =D13 + (F13/1000) + (G13/1000000) + (E13/1000000000) + (A13/100000000000) -> 1e-10 | J13: =TRIM(C13) & (COUNTIFS($C$4:$C$123, C13, $I$4:$I$123, ">"&I13) + 1) -> 111 | K13: =D13 & "/" & F13 & "/" & G13 & "/" & E13 -> /// | AA13: =_xlfn.XLOOKUP(B13, REGISTRATION!B:B, REGISTRATION!C:C, "No Team")
A14: 11 | B14: =IF(DATA_IMPORT!A12="", "", DATA_IMPORT!A12) | C14: =IF(DATA_IMPORT!D12="", "", DATA_IMPORT!D12) | H14: =IF(D14=0, COUNTIF($C$4:$C$123, C14), COUNTIFS($C$4:$C$123, C14, $I$4:$I$123, ">"&I14) + 1) -> 120 | I14: =D14 + (F14/1000) + (G14/1000000) + (E14/1000000000) + (A14/100000000000) -> 1.1e-10 | J14: =TRIM(C14) & (COUNTIFS($C$4:$C$123, C14, $I$4:$I$123, ">"&I14) + 1) -> 110 | K14: =D14 & "/" & F14 & "/" & G14 & "/" & E14 -> /// | AA14: =_xlfn.XLOOKUP(B14, REGISTRATION!B:B, REGISTRATION!C:C, "No Team")
A15: 12 | B15: =IF(DATA_IMPORT!A13="", "", DATA_IMPORT!A13) | C15: =IF(DATA_IMPORT!D13="", "", DATA_IMPORT!D13) | H15: =IF(D15=0, COUNTIF($C$4:$C$123, C15), COUNTIFS($C$4:$C$123, C15, $I$4:$I$123, ">"&I15) + 1) -> 120 | I15: =D15 + (F15/1000) + (G15/1000000) + (E15/1000000000) + (A15/100000000000) -> 1.2e-10 | J15: =TRIM(C15) & (COUNTIFS($C$4:$C$123, C15, $I$4:$I$123, ">"&I15) + 1) -> 109 | K15: =D15 & "/" & F15 & "/" & G15 & "/" & E15 -> /// | AA15: =_xlfn.XLOOKUP(B15, REGISTRATION!B:B, REGISTRATION!C:C, "No Team")
... A50: 47 | B50: =IF(DATA_IMPORT!A48="", "", DATA_IMPORT!A48) | C50: =IF(DATA_IMPORT!D48="", "", DATA_IMPORT!D48) | H50: =IF(D50=0, COUNTIF($C$4:$C$123, C50), COUNTIFS($C$4:$C$123, C50, $I$4:$I$123, ">"&I50) + 1) -> 120 | I50: =D50 + (F50/1000) + (G50/1000000) + (E50/1000000000) + (A50/100000000000) -> 4.7e-10 | J50: =TRIM(C50) & (COUNTIFS($C$4:$C$123, C50, $I$4:$I$123, ">"&I50) + 1) -> 74 | K50: =D50 & "/" & F50 & "/" & G50 & "/" & E50 -> /// | AA50: =_xlfn.XLOOKUP(B50, REGISTRATION!B:B, REGISTRATION!C:C, "No Team")
A51: 48 | B51: =IF(DATA_IMPORT!A49="", "", DATA_IMPORT!A49) | C51: =IF(DATA_IMPORT!D49="", "", DATA_IMPORT!D49) | H51: =IF(D51=0, COUNTIF($C$4:$C$123, C51), COUNTIFS($C$4:$C$123, C51, $I$4:$I$123, ">"&I51) + 1) -> 120 | I51: =D51 + (F51/1000) + (G51/1000000) + (E51/1000000000) + (A51/100000000000) -> 4.8e-10 | J51: =TRIM(C51) & (COUNTIFS($C$4:$C$123, C51, $I$4:$I$123, ">"&I51) + 1) -> 73 | K51: =D51 & "/" & F51 & "/" & G51 & "/" & E51 -> ///
A52: 49 | B52: =IF(DATA_IMPORT!A50="", "", DATA_IMPORT!A50) | C52: =IF(DATA_IMPORT!D50="", "", DATA_IMPORT!D50) | H52: =IF(D52=0, COUNTIF($C$4:$C$123, C52), COUNTIFS($C$4:$C$123, C52, $I$4:$I$123, ">"&I52) + 1) -> 120 | I52: =D52 + (F52/1000) + (G52/1000000) + (E52/1000000000) + (A52/100000000000) -> 4.9e-10 | J52: =TRIM(C52) & (COUNTIFS($C$4:$C$123, C52, $I$4:$I$123, ">"&I52) + 1) -> 72 | K52: =D52 & "/" & F52 & "/" & G52 & "/" & E52 -> ///
A53: 50 | B53: =IF(DATA_IMPORT!A51="", "", DATA_IMPORT!A51) | C53: =IF(DATA_IMPORT!D51="", "", DATA_IMPORT!D51) | H53: =IF(D53=0, COUNTIF($C$4:$C$123, C53), COUNTIFS($C$4:$C$123, C53, $I$4:$I$123, ">"&I53) + 1) -> 120 | I53: =D53 + (F53/1000) + (G53/1000000) + (E53/1000000000) + (A53/100000000000) -> 5e-10 | J53: =TRIM(C53) & (COUNTIFS($C$4:$C$123, C53, $I$4:$I$123, ">"&I53) + 1) -> 71 | K53: =D53 & "/" & F53 & "/" & G53 & "/" & E53 -> ///
A54: 51 | B54: =IF(DATA_IMPORT!A52="", "", DATA_IMPORT!A52) | C54: =IF(DATA_IMPORT!D52="", "", DATA_IMPORT!D52) | H54: =IF(D54=0, COUNTIF($C$4:$C$123, C54), COUNTIFS($C$4:$C$123, C54, $I$4:$I$123, ">"&I54) + 1) -> 120 | I54: =D54 + (F54/1000) + (G54/1000000) + (E54/1000000000) + (A54/100000000000) -> 5.1e-10 | J54: =TRIM(C54) & (COUNTIFS($C$4:$C$123, C54, $I$4:$I$123, ">"&I54) + 1) -> 70 | K54: =D54 & "/" & F54 & "/" & G54 & "/" & E54 -> ///
A55: 52 | B55: =IF(DATA_IMPORT!A53="", "", DATA_IMPORT!A53) | C55: =IF(DATA_IMPORT!D53="", "", DATA_IMPORT!D53) | H55: =IF(D55=0, COUNTIF($C$4:$C$123, C55), COUNTIFS($C$4:$C$123, C55, $I$4:$I$123, ">"&I55) + 1) -> 120 | I55: =D55 + (F55/1000) + (G55/1000000) + (E55/1000000000) + (A55/100000000000) -> 5.2e-10 | J55: =TRIM(C55) & (COUNTIFS($C$4:$C$123, C55, $I$4:$I$123, ">"&I55) + 1) -> 69 | K55: =D55 & "/" & F55 & "/" & G55 & "/" & E55 -> ///
A56: 53 | B56: =IF(DATA_IMPORT!A54="", "", DATA_IMPORT!A54) | C56: =IF(DATA_IMPORT!D54="", "", DATA_IMPORT!D54) | H56: =IF(D56=0, COUNTIF($C$4:$C$123, C56), COUNTIFS($C$4:$C$123, C56, $I$4:$I$123, ">"&I56) + 1) -> 120 | I56: =D56 + (F56/1000) + (G56/1000000) + (E56/1000000000) + (A56/100000000000) -> 5.3e-10 | J56: =TRIM(C56) & (COUNTIFS($C$4:$C$123, C56, $I$4:$I$123, ">"&I56) + 1) -> 68 | K56: =D56 & "/" & F56 & "/" & G56 & "/" & E56 -> ///
A57: 54 | B57: =IF(DATA_IMPORT!A55="", "", DATA_IMPORT!A55) | C57: =IF(DATA_IMPORT!D55="", "", DATA_IMPORT!D55) | H57: =IF(D57=0, COUNTIF($C$4:$C$123, C57), COUNTIFS($C$4:$C$123, C57, $I$4:$I$123, ">"&I57) + 1) -> 120 | I57: =D57 + (F57/1000) + (G57/1000000) + (E57/1000000000) + (A57/100000000000) -> 5.4e-10 | J57: =TRIM(C57) & (COUNTIFS($C$4:$C$123, C57, $I$4:$I$123, ">"&I57) + 1) -> 67 | K57: =D57 & "/" & F57 & "/" & G57 & "/" & E57 -> ///
A58: 55 | B58: =IF(DATA_IMPORT!A56="", "", DATA_IMPORT!A56) | C58: =IF(DATA_IMPORT!D56="", "", DATA_IMPORT!D56) | H58: =IF(D58=0, COUNTIF($C$4:$C$123, C58), COUNTIFS($C$4:$C$123, C58, $I$4:$I$123, ">"&I58) + 1) -> 120 | I58: =D58 + (F58/1000) + (G58/1000000) + (E58/1000000000) + (A58/100000000000) -> 5.5e-10 | J58: =TRIM(C58) & (COUNTIFS($C$4:$C$123, C58, $I$4:$I$123, ">"&I58) + 1) -> 66 | K58: =D58 & "/" & F58 & "/" & G58 & "/" & E58 -> ///
A59: 56 | B59: =IF(DATA_IMPORT!A57="", "", DATA_IMPORT!A57) | C59: =IF(DATA_IMPORT!D57="", "", DATA_IMPORT!D57) | H59: =IF(D59=0, COUNTIF($C$4:$C$123, C59), COUNTIFS($C$4:$C$123, C59, $I$4:$I$123, ">"&I59) + 1) -> 120 | I59: =D59 + (F59/1000) + (G59/1000000) + (E59/1000000000) + (A59/100000000000) -> 5.6e-10 | J59: =TRIM(C59) & (COUNTIFS($C$4:$C$123, C59, $I$4:$I$123, ">"&I59) + 1) -> 65 | K59: =D59 & "/" & F59 & "/" & G59 & "/" & E59 -> ///
A60: 57 | B60: =IF(DATA_IMPORT!A58="", "", DATA_IMPORT!A58) | C60: =IF(DATA_IMPORT!D58="", "", DATA_IMPORT!D58) | H60: =IF(D60=0, COUNTIF($C$4:$C$123, C60), COUNTIFS($C$4:$C$123, C60, $I$4:$I$123, ">"&I60) + 1) -> 120 | I60: =D60 + (F60/1000) + (G60/1000000) + (E60/1000000000) + (A60/100000000000) -> 5.7e-10 | J60: =TRIM(C60) & (COUNTIFS($C$4:$C$123, C60, $I$4:$I$123, ">"&I60) + 1) -> 64 | K60: =D60 & "/" & F60 & "/" & G60 & "/" & E60 -> ///
A61: 58 | B61: =IF(DATA_IMPORT!A59="", "", DATA_IMPORT!A59) | C61: =IF(DATA_IMPORT!D59="", "", DATA_IMPORT!D59) | H61: =IF(D61=0, COUNTIF($C$4:$C$123, C61), COUNTIFS($C$4:$C$123, C61, $I$4:$I$123, ">"&I61) + 1) -> 120 | I61: =D61 + (F61/1000) + (G61/1000000) + (E61/1000000000) + (A61/100000000000) -> 5.8e-10 | J61: =TRIM(C61) & (COUNTIFS($C$4:$C$123, C61, $I$4:$I$123, ">"&I61) + 1) -> 63 | K61: =D61 & "/" & F61 & "/" & G61 & "/" & E61 -> ///
A62: 59 | B62: =IF(DATA_IMPORT!A60="", "", DATA_IMPORT!A60) | C62: =IF(DATA_IMPORT!D60="", "", DATA_IMPORT!D60) | H62: =IF(D62=0, COUNTIF($C$4:$C$123, C62), COUNTIFS($C$4:$C$123, C62, $I$4:$I$123, ">"&I62) + 1) -> 120 | I62: =D62 + (F62/1000) + (G62/1000000) + (E62/1000000000) + (A62/100000000000) -> 5.9e-10 | J62: =TRIM(C62) & (COUNTIFS($C$4:$C$123, C62, $I$4:$I$123, ">"&I62) + 1) -> 62 | K62: =D62 & "/" & F62 & "/" & G62 & "/" & E62 -> ///
... A123: 120 | B123: =IF(DATA_IMPORT!A121="", "", DATA_IMPORT!A121) | C123: =IF(DATA_IMPORT!D121="", "", DATA_IMPORT!D121) | H123: =IF(D123=0, COUNTIF($C$4:$C$123, C123), COUNTIFS($C$4:$C$123, C123, $I$4:$I$123, ">"&I123) + 1) -> 120 | I123: =D123 + (F123/1000) + (G123/1000000) + (E123/1000000000) + (A123/100000000000) -> 1.2e-09 | J123: =TRIM(C123) & (COUNTIFS($C$4:$C$123, C123, $I$4:$I$123, ">"&I123) + 1) -> 1 | K123: =D123 & "/" & F123 & "/" & G123 & "/" & E123 -> ///
B124: =IF(DATA_IMPORT!A122="", "", DATA_IMPORT!A122) | C124: =IF(DATA_IMPORT!D122="", "", DATA_IMPORT!D122) | H124: =IF(D124=0, COUNTIFS($C$4:$C$123, C124, $B$4:$B$123, "<>"), COUNTIFS($C$4:$C$123, C124, $D$4:$D$123, ">"&D124) + 1) -> 120 | J124: =TRIM(C124) & (COUNTIFS($C$4:$C$123, C124, $I$4:$I$123, ">"&I124) + 1) -> 1
B125: =IF(DATA_IMPORT!A123="", "", DATA_IMPORT!A123) | C125: =IF(DATA_IMPORT!D123="", "", DATA_IMPORT!D123) | H125: =IF(D125=0, COUNTIFS($C$4:$C$123, C125, $B$4:$B$123, "<>"), COUNTIFS($C$4:$C$123, C125, $D$4:$D$123, ">"&D125) + 1) -> 120 | J125: =TRIM(C125) & (COUNTIFS($C$4:$C$123, C125, $I$4:$I$123, ">"&I125) + 1) -> 1
B126: =IF(DATA_IMPORT!A124="", "", DATA_IMPORT!A124) | C126: =IF(DATA_IMPORT!D124="", "", DATA_IMPORT!D124) | H126: =IF(D126=0, COUNTIFS($C$4:$C$123, C126, $B$4:$B$123, "<>"), COUNTIFS($C$4:$C$123, C126, $D$4:$D$123, ">"&D126) + 1) -> 120 | J126: =TRIM(C126) & (COUNTIFS($C$4:$C$123, C126, $I$4:$I$123, ">"&I126) + 1) -> 1
B127: =IF(DATA_IMPORT!A125="", "", DATA_IMPORT!A125) | C127: =IF(DATA_IMPORT!D125="", "", DATA_IMPORT!D125) | H127: =IF(D127=0, COUNTIFS($C$4:$C$123, C127, $B$4:$B$123, "<>"), COUNTIFS($C$4:$C$123, C127, $D$4:$D$123, ">"&D127) + 1) -> 120 | J127: =TRIM(C127) & (COUNTIFS($C$4:$C$123, C127, $I$4:$I$123, ">"&I127) + 1) -> 1
B128: =IF(DATA_IMPORT!A126="", "", DATA_IMPORT!A126) | C128: =IF(DATA_IMPORT!D126="", "", DATA_IMPORT!D126) | H128: =IF(D128=0, COUNTIFS($C$4:$C$123, C128, $B$4:$B$123, "<>"), COUNTIFS($C$4:$C$123, C128, $D$4:$D$123, ">"&D128) + 1) -> 120 | J128: =TRIM(C128) & (COUNTIFS($C$4:$C$123, C128, $I$4:$I$123, ">"&I128) + 1) -> 1
B129: =IF(DATA_IMPORT!A127="", "", DATA_IMPORT!A127) | C129: =IF(DATA_IMPORT!D127="", "", DATA_IMPORT!D127) | H129: =IF(D129=0, COUNTIFS($C$4:$C$123, C129, $B$4:$B$123, "<>"), COUNTIFS($C$4:$C$123, C129, $D$4:$D$123, ">"&D129) + 1) -> 120 | J129: =TRIM(C129) & (COUNTIFS($C$4:$C$123, C129, $I$4:$I$123, ">"&I129) + 1) -> 1
B130: =IF(DATA_IMPORT!A128="", "", DATA_IMPORT!A128) | C130: =IF(DATA_IMPORT!D128="", "", DATA_IMPORT!D128) | H130: =IF(D130=0, COUNTIFS($C$4:$C$123, C130, $B$4:$B$123, "<>"), COUNTIFS($C$4:$C$123, C130, $D$4:$D$123, ">"&D130) + 1) -> 120 | J130: =TRIM(C130) & (COUNTIFS($C$4:$C$123, C130, $I$4:$I$123, ">"&I130) + 1) -> 1
B131: =IF(DATA_IMPORT!A129="", "", DATA_IMPORT!A129) | C131: =IF(DATA_IMPORT!D129="", "", DATA_IMPORT!D129) | H131: =IF(D131=0, COUNTIFS($C$4:$C$123, C131, $B$4:$B$123, "<>"), COUNTIFS($C$4:$C$123, C131, $D$4:$D$123, ">"&D131) + 1) -> 120 | J131: =TRIM(C131) & (COUNTIFS($C$4:$C$123, C131, $I$4:$I$123, ">"&I131) + 1) -> 1
B132: =IF(DATA_IMPORT!A130="", "", DATA_IMPORT!A130) | C132: =IF(DATA_IMPORT!D130="", "", DATA_IMPORT!D130) | H132: =IF(D132=0, COUNTIFS($C$4:$C$123, C132, $B$4:$B$123, "<>"), COUNTIFS($C$4:$C$123, C132, $D$4:$D$123, ">"&D132) + 1) -> 120 | J132: =TRIM(C132) & (COUNTIFS($C$4:$C$123, C132, $I$4:$I$123, ">"&I132) + 1) -> 1
B133: =IF(DATA_IMPORT!A131="", "", DATA_IMPORT!A131) | C133: =IF(DATA_IMPORT!D131="", "", DATA_IMPORT!D131) | H133: =IF(D133=0, COUNTIFS($C$4:$C$123, C133, $B$4:$B$123, "<>"), COUNTIFS($C$4:$C$123, C133, $D$4:$D$123, ">"&D133) + 1) -> 120 | J133: =TRIM(C133) & (COUNTIFS($C$4:$C$123, C133, $I$4:$I$123, ">"&I133) + 1) -> 1
B134: =IF(DATA_IMPORT!A132="", "", DATA_IMPORT!A132) | C134: =IF(DATA_IMPORT!D132="", "", DATA_IMPORT!D132) | H134: =IF(D134=0, COUNTIFS($C$4:$C$123, C134, $B$4:$B$123, "<>"), COUNTIFS($C$4:$C$123, C134, $D$4:$D$123, ">"&D134) + 1) -> 120 | J134: =TRIM(C134) & (COUNTIFS($C$4:$C$123, C134, $I$4:$I$123, ">"&I134) + 1) -> 1
...

Sheet ZONE 1
B1: ZONE RESULTS - DAY 1
A2: POS | B2: NAME | C2: TEAM | D2: P.N.B.S | E2: PT | F2: POS | G2: NAME | H2: TEAM | I2: P.N.B.S | J2: PT | K2: POS | L2: NAME | M2: TEAM | N2: P.N.B.S | O2: PT | P2: POS | Q2: NAME | R2: TEAM | S2: P.N.B.S | T2: PT
A3: 1 | B3: =IFERROR(INDEX('DAY 1 SCORES'!$B:$B, MATCH("RED" & $A3, 'DAY 1 SCORES'!$J:$J, 0)), "") | C3: =IFERROR(INDEX(DATA_IMPORT!$B:$B, MATCH(B3, DATA_IMPORT!$A:$A, 0)), "") | D3: =IFERROR(VLOOKUP($B3, 'DAY 1 SCORES'!$B:$K, 10, FALSE), "") -> /// | E3: =IF(B3="", "", IFERROR(INDEX('DAY 1 SCORES'!$H:$H, MATCH(B3, 'DAY 1 SCORES'!$B:$B, 0)), "")) | F3: 1 | G3: =IFERROR(INDEX('DAY 1 SCORES'!$B:$B, MATCH("YELLOW" & $A3, 'DAY 1 SCORES'!$J:$J, 0)), "") | H3: =IFERROR(INDEX(DATA_IMPORT!$B:$B, MATCH(G3, DATA_IMPORT!$A:$A, 0)), "") | I3: =IFERROR(VLOOKUP($G3, 'DAY 1 SCORES'!$B:$K, 10, FALSE), "") -> /// | J3: =IF(G3="", "", IFERROR(INDEX('DAY 1 SCORES'!$H:$H, MATCH(G3, 'DAY 1 SCORES'!$B:$B, 0)), "")) | K3: 1 | L3: =IFERROR(INDEX('DAY 1 SCORES'!$B:$B, MATCH("GREEN" & $A3, 'DAY 1 SCORES'!$J:$J, 0)), "") | M3: =IFERROR(INDEX(DATA_IMPORT!$B:$B, MATCH(L3, DATA_IMPORT!$A:$A, 0)), "") | N3: =IFERROR(VLOOKUP($L3, 'DAY 1 SCORES'!$B:$K, 10, FALSE), "") -> /// | O3: =IF(L3="", "", IFERROR(INDEX('DAY 1 SCORES'!$H:$H, MATCH(L3, 'DAY 1 SCORES'!$B:$B, 0)), "")) | P3: 1 | Q3: =IFERROR(INDEX('DAY 1 SCORES'!$B:$B, MATCH("BLUE" & $A3, 'DAY 1 SCORES'!$J:$J, 0)), "") | R3: =IFERROR(INDEX(DATA_IMPORT!$B:$B, MATCH(Q3, DATA_IMPORT!$A:$A, 0)), "") | S3: =IFERROR(VLOOKUP($Q3, 'DAY 1 SCORES'!$B:$K, 10, FALSE), "") -> /// | T3: =IF(Q3="", "", IFERROR(INDEX('DAY 1 SCORES'!$H:$H, MATCH(Q3, 'DAY 1 SCORES'!$B:$B, 0)), ""))
A4: 2 | B4: =IFERROR(INDEX('DAY 1 SCORES'!$B:$B, MATCH("RED" & $A4, 'DAY 1 SCORES'!$J:$J, 0)), "") | C4: =IFERROR(INDEX(DATA_IMPORT!$B:$B, MATCH(B4, DATA_IMPORT!$A:$A, 0)), "") | D4: =IFERROR(VLOOKUP($B4, 'DAY 1 SCORES'!$B:$K, 10, FALSE), "") -> /// | E4: =IF(B4="", "", IFERROR(INDEX('DAY 1 SCORES'!$H:$H, MATCH(B4, 'DAY 1 SCORES'!$B:$B, 0)), "")) | F4: 2 | G4: =IFERROR(INDEX('DAY 1 SCORES'!$B:$B, MATCH("YELLOW" & $A4, 'DAY 1 SCORES'!$J:$J, 0)), "") | H4: =IFERROR(INDEX(DATA_IMPORT!$B:$B, MATCH(G4, DATA_IMPORT!$A:$A, 0)), "") | I4: =IFERROR(VLOOKUP($G4, 'DAY 1 SCORES'!$B:$K, 10, FALSE), "") -> /// | J4: =IF(G4="", "", IFERROR(INDEX('DAY 1 SCORES'!$H:$H, MATCH(G4, 'DAY 1 SCORES'!$B:$B, 0)), "")) | K4: 2 | L4: =IFERROR(INDEX('DAY 1 SCORES'!$B:$B, MATCH("GREEN" & $A4, 'DAY 1 SCORES'!$J:$J, 0)), "") | M4: =IFERROR(INDEX(DATA_IMPORT!$B:$B, MATCH(L4, DATA_IMPORT!$A:$A, 0)), "") | N4: =IFERROR(VLOOKUP($L4, 'DAY 1 SCORES'!$B:$K, 10, FALSE), "") -> /// | O4: =IF(L4="", "", IFERROR(INDEX('DAY 1 SCORES'!$H:$H, MATCH(L4, 'DAY 1 SCORES'!$B:$B, 0)), "")) | P4: 2 | Q4: =IFERROR(INDEX('DAY 1 SCORES'!$B:$B, MATCH("BLUE" & $A4, 'DAY 1 SCORES'!$J:$J, 0)), "") | R4: =IFERROR(INDEX(DATA_IMPORT!$B:$B, MATCH(Q4, DATA_IMPORT!$A:$A, 0)), "") | S4: =IFERROR(VLOOKUP($Q4, 'DAY 1 SCORES'!$B:$K, 10, FALSE), "") -> /// | T4: =IF(Q4="", "", IFERROR(INDEX('DAY 1 SCORES'!$H:$H, MATCH(Q4, 'DAY 1 SCORES'!$B:$B, 0)), ""))
A5: 3 | B5: =IFERROR(INDEX('DAY 1 SCORES'!$B:$B, MATCH("RED" & $A5, 'DAY 1 SCORES'!$J:$J, 0)), "") | C5: =IFERROR(INDEX(DATA_IMPORT!$B:$B, MATCH(B5, DATA_IMPORT!$A:$A, 0)), "") | D5: =IFERROR(VLOOKUP($B5, 'DAY 1 SCORES'!$B:$K, 10, FALSE), "") -> /// | E5: =IF(B5="", "", IFERROR(INDEX('DAY 1 SCORES'!$H:$H, MATCH(B5, 'DAY 1 SCORES'!$B:$B, 0)), "")) | F5: 3 | G5: =IFERROR(INDEX('DAY 1 SCORES'!$B:$B, MATCH("YELLOW" & $A5, 'DAY 1 SCORES'!$J:$J, 0)), "") | H5: =IFERROR(INDEX(DATA_IMPORT!$B:$B, MATCH(G5, DATA_IMPORT!$A:$A, 0)), "") | I5: =IFERROR(VLOOKUP($G5, 'DAY 1 SCORES'!$B:$K, 10, FALSE), "") -> /// | J5: =IF(G5="", "", IFERROR(INDEX('DAY 1 SCORES'!$H:$H, MATCH(G5, 'DAY 1 SCORES'!$B:$B, 0)), "")) | K5: 3 | L5: =IFERROR(INDEX('DAY 1 SCORES'!$B:$B, MATCH("GREEN" & $A5, 'DAY 1 SCORES'!$J:$J, 0)), "") | M5: =IFERROR(INDEX(DATA_IMPORT!$B:$B, MATCH(L5, DATA_IMPORT!$A:$A, 0)), "") | N5: =IFERROR(VLOOKUP($L5, 'DAY 1 SCORES'!$B:$K, 10, FALSE), "") -> /// | O5: =IF(L5="", "", IFERROR(INDEX('DAY 1 SCORES'!$H:$H, MATCH(L5, 'DAY 1 SCORES'!$B:$B, 0)), "")) | P5: 3 | Q5: =IFERROR(INDEX('DAY 1 SCORES'!$B:$B, MATCH("BLUE" & $A5, 'DAY 1 SCORES'!$J:$J, 0)), "") | R5: =IFERROR(INDEX(DATA_IMPORT!$B:$B, MATCH(Q5, DATA_IMPORT!$A:$A, 0)), "") | S5: =IFERROR(VLOOKUP($Q5, 'DAY 1 SCORES'!$B:$K, 10, FALSE), "") -> /// | T5: =IF(Q5="", "", IFERROR(INDEX('DAY 1 SCORES'!$H:$H, MATCH(Q5, 'DAY 1 SCORES'!$B:$B, 0)), ""))
A6: 4 | B6: =IFERROR(INDEX('DAY 1 SCORES'!$B:$B, MATCH("RED" & $A6, 'DAY 1 SCORES'!$J:$J, 0)), "") | C6: =IFERROR(INDEX(DATA_IMPORT!$B:$B, MATCH(B6, DATA_IMPORT!$A:$A, 0)), "") | D6: =IFERROR(VLOOKUP($B6, 'DAY 1 SCORES'!$B:$K, 10, FALSE), "") -> /// | E6: =IF(B6="", "", IFERROR(INDEX('DAY 1 SCORES'!$H:$H, MATCH(B6, 'DAY 1 SCORES'!$B:$B, 0)), "")) | F6: 4 | G6: =IFERROR(INDEX('DAY 1 SCORES'!$B:$B, MATCH("YELLOW" & $A6, 'DAY 1 SCORES'!$J:$J, 0)), "") | H6: =IFERROR(INDEX(DATA_IMPORT!$B:$B, MATCH(G6, DATA_IMPORT!$A:$A, 0)), "") | I6: =IFERROR(VLOOKUP($G6, 'DAY 1 SCORES'!$B:$K, 10, FALSE), "") -> /// | J6: =IF(G6="", "", IFERROR(INDEX('DAY 1 SCORES'!$H:$H, MATCH(G6, 'DAY 1 SCORES'!$B:$B, 0)), "")) | K6: 4 | L6: =IFERROR(INDEX('DAY 1 SCORES'!$B:$B, MATCH("GREEN" & $A6, 'DAY 1 SCORES'!$J:$J, 0)), "") | M6: =IFERROR(INDEX(DATA_IMPORT!$B:$B, MATCH(L6, DATA_IMPORT!$A:$A, 0)), "") | N6: =IFERROR(VLOOKUP($L6, 'DAY 1 SCORES'!$B:$K, 10, FALSE), "") -> /// | O6: =IF(L6="", "", IFERROR(INDEX('DAY 1 SCORES'!$H:$H, MATCH(L6, 'DAY 1 SCORES'!$B:$B, 0)), "")) | P6: 4 | Q6: =IFERROR(INDEX('DAY 1 SCORES'!$B:$B, MATCH("BLUE" & $A6, 'DAY 1 SCORES'!$J:$J, 0)), "") | R6: =IFERROR(INDEX(DATA_IMPORT!$B:$B, MATCH(Q6, DATA_IMPORT!$A:$A, 0)), "") | S6: =IFERROR(VLOOKUP($Q6, 'DAY 1 SCORES'!$B:$K, 10, FALSE), "") -> /// | T6: =IF(Q6="", "", IFERROR(INDEX('DAY 1 SCORES'!$H:$H, MATCH(Q6, 'DAY 1 SCORES'!$B:$B, 0)), ""))
A7: 5 | B7: =IFERROR(INDEX('DAY 1 SCORES'!$B:$B, MATCH("RED" & $A7, 'DAY 1 SCORES'!$J:$J, 0)), "") | C7: =IFERROR(INDEX(DATA_IMPORT!$B:$B, MATCH(B7, DATA_IMPORT!$A:$A, 0)), "") | D7: =IFERROR(VLOOKUP($B7, 'DAY 1 SCORES'!$B:$K, 10, FALSE), "") -> /// | E7: =IF(B7="", "", IFERROR(INDEX('DAY 1 SCORES'!$H:$H, MATCH(B7, 'DAY 1 SCORES'!$B:$B, 0)), "")) | F7: 5 | G7: =IFERROR(INDEX('DAY 1 SCORES'!$B:$B, MATCH("YELLOW" & $A7, 'DAY 1 SCORES'!$J:$J, 0)), "") | H7: =IFERROR(INDEX(DATA_IMPORT!$B:$B, MATCH(G7, DATA_IMPORT!$A:$A, 0)), "") | I7: =IFERROR(VLOOKUP($G7, 'DAY 1 SCORES'!$B:$K, 10, FALSE), "") -> /// | J7: =IF(G7="", "", IFERROR(INDEX('DAY 1 SCORES'!$H:$H, MATCH(G7, 'DAY 1 SCORES'!$B:$B, 0)), "")) | K7: 5 | L7: =IFERROR(INDEX('DAY 1 SCORES'!$B:$B, MATCH("GREEN" & $A7, 'DAY 1 SCORES'!$J:$J, 0)), "") | M7: =IFERROR(INDEX(DATA_IMPORT!$B:$B, MATCH(L7, DATA_IMPORT!$A:$A, 0)), "") | N7: =IFERROR(VLOOKUP($L7, 'DAY 1 SCORES'!$B:$K, 10, FALSE), "") -> /// | O7: =IF(L7="", "", IFERROR(INDEX('DAY 1 SCORES'!$H:$H, MATCH(L7, 'DAY 1 SCORES'!$B:$B, 0)), "")) | P7: 5 | Q7: =IFERROR(INDEX('DAY 1 SCORES'!$B:$B, MATCH("BLUE" & $A7, 'DAY 1 SCORES'!$J:$J, 0)), "") | R7: =IFERROR(INDEX(DATA_IMPORT!$B:$B, MATCH(Q7, DATA_IMPORT!$A:$A, 0)), "") | S7: =IFERROR(VLOOKUP($Q7, 'DAY 1 SCORES'!$B:$K, 10, FALSE), "") -> /// | T7: =IF(Q7="", "", IFERROR(INDEX('DAY 1 SCORES'!$H:$H, MATCH(Q7, 'DAY 1 SCORES'!$B:$B, 0)), ""))
A8: 6 | B8: =IFERROR(INDEX('DAY 1 SCORES'!$B:$B, MATCH("RED" & $A8, 'DAY 1 SCORES'!$J:$J, 0)), "") | C8: =IFERROR(INDEX(DATA_IMPORT!$B:$B, MATCH(B8, DATA_IMPORT!$A:$A, 0)), "") | D8: =IFERROR(VLOOKUP($B8, 'DAY 1 SCORES'!$B:$K, 10, FALSE), "") -> /// | E8: =IF(B8="", "", IFERROR(INDEX('DAY 1 SCORES'!$H:$H, MATCH(B8, 'DAY 1 SCORES'!$B:$B, 0)), "")) | F8: 6 | G8: =IFERROR(INDEX('DAY 1 SCORES'!$B:$B, MATCH("YELLOW" & $A8, 'DAY 1 SCORES'!$J:$J, 0)), "") | H8: =IFERROR(INDEX(DATA_IMPORT!$B:$B, MATCH(G8, DATA_IMPORT!$A:$A, 0)), "") | I8: =IFERROR(VLOOKUP($G8, 'DAY 1 SCORES'!$B:$K, 10, FALSE), "") -> /// | J8: =IF(G8="", "", IFERROR(INDEX('DAY 1 SCORES'!$H:$H, MATCH(G8, 'DAY 1 SCORES'!$B:$B, 0)), "")) | K8: 6 | L8: =IFERROR(INDEX('DAY 1 SCORES'!$B:$B, MATCH("GREEN" & $A8, 'DAY 1 SCORES'!$J:$J, 0)), "") | M8: =IFERROR(INDEX(DATA_IMPORT!$B:$B, MATCH(L8, DATA_IMPORT!$A:$A, 0)), "") | N8: =IFERROR(VLOOKUP($L8, 'DAY 1 SCORES'!$B:$K, 10, FALSE), "") -> /// | O8: =IF(L8="", "", IFERROR(INDEX('DAY 1 SCORES'!$H:$H, MATCH(L8, 'DAY 1 SCORES'!$B:$B, 0)), "")) | P8: 6 | Q8: =IFERROR(INDEX('DAY 1 SCORES'!$B:$B, MATCH("BLUE" & $A8, 'DAY 1 SCORES'!$J:$J, 0)), "") | R8: =IFERROR(INDEX(DATA_IMPORT!$B:$B, MATCH(Q8, DATA_IMPORT!$A:$A, 0)), "") | S8: =IFERROR(VLOOKUP($Q8, 'DAY 1 SCORES'!$B:$K, 10, FALSE), "") -> /// | T8: =IF(Q8="", "", IFERROR(INDEX('DAY 1 SCORES'!$H:$H, MATCH(Q8, 'DAY 1 SCORES'!$B:$B, 0)), ""))
A9: 7 | B9: =IFERROR(INDEX('DAY 1 SCORES'!$B:$B, MATCH("RED" & $A9, 'DAY 1 SCORES'!$J:$J, 0)), "") | C9: =IFERROR(INDEX(DATA_IMPORT!$B:$B, MATCH(B9, DATA_IMPORT!$A:$A, 0)), "") | D9: =IFERROR(VLOOKUP($B9, 'DAY 1 SCORES'!$B:$K, 10, FALSE), "") -> /// | E9: =IF(B9="", "", IFERROR(INDEX('DAY 1 SCORES'!$H:$H, MATCH(B9, 'DAY 1 SCORES'!$B:$B, 0)), "")) | F9: 7 | G9: =IFERROR(INDEX('DAY 1 SCORES'!$B:$B, MATCH("YELLOW" & $A9, 'DAY 1 SCORES'!$J:$J, 0)), "") | H9: =IFERROR(INDEX(DATA_IMPORT!$B:$B, MATCH(G9, DATA_IMPORT!$A:$A, 0)), "") | I9: =IFERROR(VLOOKUP($G9, 'DAY 1 SCORES'!$B:$K, 10, FALSE), "") -> /// | J9: =IF(G9="", "", IFERROR(INDEX('DAY 1 SCORES'!$H:$H, MATCH(G9, 'DAY 1 SCORES'!$B:$B, 0)), "")) | K9: 7 | L9: =IFERROR(INDEX('DAY 1 SCORES'!$B:$B, MATCH("GREEN" & $A9, 'DAY 1 SCORES'!$J:$J, 0)), "") | M9: =IFERROR(INDEX(DATA_IMPORT!$B:$B, MATCH(L9, DATA_IMPORT!$A:$A, 0)), "") | N9: =IFERROR(VLOOKUP($L9, 'DAY 1 SCORES'!$B:$K, 10, FALSE), "") -> /// | O9: =IF(L9="", "", IFERROR(INDEX('DAY 1 SCORES'!$H:$H, MATCH(L9, 'DAY 1 SCORES'!$B:$B, 0)), "")) | P9: 7 | Q9: =IFERROR(INDEX('DAY 1 SCORES'!$B:$B, MATCH("BLUE" & $A9, 'DAY 1 SCORES'!$J:$J, 0)), "") | R9: =IFERROR(INDEX(DATA_IMPORT!$B:$B, MATCH(Q9, DATA_IMPORT!$A:$A, 0)), "") | S9: =IFERROR(VLOOKUP($Q9, 'DAY 1 SCORES'!$B:$K, 10, FALSE), "") -> /// | T9: =IF(Q9="", "", IFERROR(INDEX('DAY 1 SCORES'!$H:$H, MATCH(Q9, 'DAY 1 SCORES'!$B:$B, 0)), ""))
A10: 8 | B10: =IFERROR(INDEX('DAY 1 SCORES'!$B:$B, MATCH("RED" & $A10, 'DAY 1 SCORES'!$J:$J, 0)), "") | C10: =IFERROR(INDEX(DATA_IMPORT!$B:$B, MATCH(B10, DATA_IMPORT!$A:$A, 0)), "") | D10: =IFERROR(VLOOKUP($B10, 'DAY 1 SCORES'!$B:$K, 10, FALSE), "") -> /// | E10: =IF(B10="", "", IFERROR(INDEX('DAY 1 SCORES'!$H:$H, MATCH(B10, 'DAY 1 SCORES'!$B:$B, 0)), "")) | F10: 8 | G10: =IFERROR(INDEX('DAY 1 SCORES'!$B:$B, MATCH("YELLOW" & $A10, 'DAY 1 SCORES'!$J:$J, 0)), "") | H10: =IFERROR(INDEX(DATA_IMPORT!$B:$B, MATCH(G10, DATA_IMPORT!$A:$A, 0)), "") | I10: =IFERROR(VLOOKUP($G10, 'DAY 1 SCORES'!$B:$K, 10, FALSE), "") -> /// | J10: =IF(G10="", "", IFERROR(INDEX('DAY 1 SCORES'!$H:$H, MATCH(G10, 'DAY 1 SCORES'!$B:$B, 0)), "")) | K10: 8 | L10: =IFERROR(INDEX('DAY 1 SCORES'!$B:$B, MATCH("GREEN" & $A10, 'DAY 1 SCORES'!$J:$J, 0)), "") | M10: =IFERROR(INDEX(DATA_IMPORT!$B:$B, MATCH(L10, DATA_IMPORT!$A:$A, 0)), "") | N10: =IFERROR(VLOOKUP($L10, 'DAY 1 SCORES'!$B:$K, 10, FALSE), "") -> /// | O10: =IF(L10="", "", IFERROR(INDEX('DAY 1 SCORES'!$H:$H, MATCH(L10, 'DAY 1 SCORES'!$B:$B, 0)), "")) | P10: 8 | Q10: =IFERROR(INDEX('DAY 1 SCORES'!$B:$B, MATCH("BLUE" & $A10, 'DAY 1 SCORES'!$J:$J, 0)), "") | R10: =IFERROR(INDEX(DATA_IMPORT!$B:$B, MATCH(Q10, DATA_IMPORT!$A:$A, 0)), "") | S10: =IFERROR(VLOOKUP($Q10, 'DAY 1 SCORES'!$B:$K, 10, FALSE), "") -> /// | T10: =IF(Q10="", "", IFERROR(INDEX('DAY 1 SCORES'!$H:$H, MATCH(Q10, 'DAY 1 SCORES'!$B:$B, 0)), ""))
